Workbook

Sheet Итоги
B2: "FBO", "FBS", "Гибрид", "Гибрид с Fulllog (3PL)" - Итоговая экономика
B5: Выручка: Гибрид с Fulllog (3PL) | E5: Валовая прибыль: Гибрид с Fulllog (3PL) | H5: Операционная прибыль: Гибрид с Fulllog (3PL) | K5: Операционная маржа: Гибрид с Fulllog (3PL)
B6: =F22 -> 13668020 | E6: =F24 -> 7765680 | H6: =F42 -> 3064646.8 | K6: =F43 -> 0.22422025
B10: КОНФИГУРАЦИЯ СЦЕНАРИЕВ | H10: Рекомендация
B11: Показатель | C11: FBO | D11: FBS | E11: Гибрид | F11: Гибрид с Fulllog (3PL) | H11: =IF(MAX(C42:F42)=F42,"Гибрид с Fulllog (3PL)",IF(MAX(C42:F42)=E42,"Гибрид",IF(MAX(C42:F42)=D42,"FBS","FBO"))) -> Гибрид с Fulllog (3PL)
B12: SKU → FBO, шт. | C12: =COUNTIF(Модель!$S$5:$S$44,"<>Пауза") -> 38 | D12: =0 -> 0 | E12: =COUNTIF(Модель!$S$5:$S$44,"FBO") -> 17 | F12: =E12 -> 17
B13: SKU → FBS, шт. | C13: =0 -> 0 | D13: =COUNTIF(Модель!$S$5:$S$44,"<>Пауза") -> 38 | E13: =COUNTIF(Модель!$S$5:$S$44,"FBS") -> 21 | F13: =E13 -> 21 | H13: При текущих тарифах передача FBS-операций Fulllog экономически выгоднее, чем самостоятельное создание и обслуживание полного FBS-контура Sportmaster
B14: SKU → Пауза, шт. | C14: =COUNTIF(Модель!$S$5:$S$44,"Пауза") -> 2 | D14: =COUNTIF(Модель!$S$5:$S$44,"Пауза") -> 2 | E14: =COUNTIF(Модель!$S$5:$S$44,"Пауза") -> 2 | F14: =COUNTIF(Модель!$S$5:$S$44,"Пауза") -> 2
B15: Рейсы собственного FBS → Ozon, раз/мес. | C15: =0 -> 0 | D15: =MAX(ROUNDUP(SUMPRODUCT((Модель!$S$5:$S$44<>"Пауза")*Модель!$AK$5:$AK$44)/Модель!$C$48/Модель!$C$66,0),ROUNDUP(SUMPRODUCT((Модель!$S$5:$S$44<>"Пауза")*Модель!$AY$5:$AY$44)/Модель!$C$48/Модель!$C$67,0))*Модель!$C$48 -> 30 | E15: =MAX(ROUNDUP(SUM(Модель!$U$5:$U$44)/Модель!$C$48/Модель!$C$66,0),ROUNDUP(SUM(Модель!$V$5:$V$44)/Модель!$C$48/Модель!$C$67,0))*Модель!$C$48 -> 30 | F15: =0 -> 0
B16: SLA FBS: передано ≤24 ч, % | C16: =0 -> 0 | D16: =1-Модель!$C$50 -> 0.9 | E16: =1-Модель!$C$50 -> 0.9 | F16: =1-Модель!$C$50 -> 0.9 | H16: SM-0020 и SM-0037 формируют отрицательный денежный эффект независимо от схемы исполнения — рекомендуем вывести их из активных продаж до пересмотра цены, спроса или себестоимости.
B18: P&L ПО СЦЕНАРИЯМ
B20: ДОХОДЫ И СЕБЕСТОИМОСТЬ
B21: Статья | C21: FBO | D21: FBS | E21: Гибрид | F21: Гибрид с Fulllog (3PL)
B22: Выручка | C22: =SUMIFS(Модель!$Z$5:$Z$44,Модель!$S$5:$S$44,"<>Пауза") -> 14530290 | D22: =SUMIFS(Модель!$AN$5:$AN$44,Модель!$S$5:$S$44,"<>Пауза") -> 12876790 | E22: =SUM(Модель!$BB$5:$BB$44) -> 13668020 | F22: =E22 -> 13668020
B23: Себестоимость выкупов | C23: =SUMIFS(Модель!$AA$5:$AA$44,Модель!$S$5:$S$44,"<>Пауза") -> 6332650 | D23: =SUMIFS(Модель!$AO$5:$AO$44,Модель!$S$5:$S$44,"<>Пауза") -> 5594240 | E23: =SUM(Модель!$BC$5:$BC$44) -> 5902340 | F23: =E23 -> 5902340
B24: Валовая прибыль | C24: =C22-C23 -> 8197640 | D24: =D22-D23 -> 7282550 | E24: =E22-E23 -> 7765680 | F24: =F22-F23 -> 7765680
B25: ОПЕРАЦИОННЫЕ РАСХОДЫ | J25: Сценарий | K25: Операционная прибыль
B26: Статья | C26: FBO | D26: FBS | E26: Гибрид | F26: Гибрид с Fulllog (3PL) | J26: FBO | K26: =C42 -> 2151647.7
B27: Комиссия Ozon | C27: =SUMIFS(Модель!$AB$5:$AB$44,Модель!$S$5:$S$44,"<>Пауза") -> 2246020.2 | D27: =SUMIFS(Модель!$AP$5:$AP$44,Модель!$S$5:$S$44,"<>Пауза") -> 1865684 | E27: =SUM(Модель!$BD$5:$BD$44) -> 2064528.4 | F27: =E27 -> 2064528.4 | J27: FBS | K27: =D42 -> 2608490.2
B28: Эквайринг | C28: =SUMIFS(Модель!$AC$5:$AC$44,Модель!$S$5:$S$44,"<>Пауза") -> 217954.35 | D28: =SUMIFS(Модель!$AQ$5:$AQ$44,Модель!$S$5:$S$44,"<>Пауза") -> 193151.85 | E28: =SUM(Модель!$BE$5:$BE$44) -> 205020.3 | F28: =E28 -> 205020.3 | J28: Гибрид | K28: =E42 -> 2938795.1
B29: Первая миля до первой внешней точки | C29: =SUMPRODUCT((Модель!$S$5:$S$44<>"Пауза")*Модель!$X$5:$X$44*Модель!$J$5:$J$44)*'Затраты продавца'!$B$12 -> 151335.48 | D29: =D15*'Затраты продавца'!$B$8 -> 75000 | E29: =SUM(Модель!$BI$5:$BI$44)+E15*'Затраты продавца'!$B$8 -> 119332.49 | F29: =SUM(Модель!$BI$5:$BI$44)+SUM(Модель!$V$5:$V$44)*1000*'Fulllog 3PL'!$L$7 -> 138580.02 | J29: Гибрид с Fulllog | K29: =F42 -> 3064646.8
B30: Хранение | C30: =SUMIFS(Модель!$AF$5:$AF$44,Модель!$S$5:$S$44,"<>Пауза") -> 2097850.1 | D30: =SUMIFS(Модель!$AT$5:$AT$44,Модель!$S$5:$S$44,"<>Пауза") -> 674342.55 | E30: =SUM(Модель!$BH$5:$BH$44) -> 1044600.1 | F30: =SUMIFS(Модель!$BH$5:$BH$44,Модель!$S$5:$S$44,"FBO")+'Fulllog 3PL'!$D$12 -> 918219.83
B31: Сборка / подбор | C31: =0 -> 0 | D31: =SUMPRODUCT((Модель!$S$5:$S$44<>"Пауза")*Модель!$AK$5:$AK$44)*'Затраты продавца'!$B$6 -> 380880 | E31: =SUM(Модель!$U$5:$U$44)*'Затраты продавца'!$B$6 -> 70500 | F31: =SUM('Fulllog 3PL'!$D$11,'Fulllog 3PL'!$D$13,'Fulllog 3PL'!$D$15,'Fulllog 3PL'!$D$19) -> 21150
B32: Упаковка | C32: =0 -> 0 | D32: =SUMPRODUCT((Модель!$S$5:$S$44<>"Пауза")*Модель!$AK$5:$AK$44)*'Затраты продавца'!$B$7 -> 63480 | E32: =SUM(Модель!$U$5:$U$44)*'Затраты продавца'!$B$7 -> 11750 | F32: ='Fulllog 3PL'!$D$14 -> 28410
B33: Передача FBS-заказов в Ozon | C33: =0 -> 0 | D33: =SUMIFS(Модель!$AV$5:$AV$44,Модель!$S$5:$S$44,"<>Пауза") -> 63480 | E33: =SUM(Модель!$BK$5:$BK$44) -> 11750 | F33: ='Fulllog 3PL'!$D$16 -> 29375
B34: Прямая логистика Ozon | C34: =SUMIFS(Модель!$AD$5:$AD$44,Модель!$S$5:$S$44,"<>Пауза") -> 962020.39 | D34: =SUMIFS(Модель!$AR$5:$AR$44,Модель!$S$5:$S$44,"<>Пауза") -> 856216.43 | E34: =SUM(Модель!$BF$5:$BF$44) -> 906738.53 | F34: =E34 -> 906738.53
B35: Последняя миля Ozon | C35: =SUMIFS(Модель!$AE$5:$AE$44,Модель!$S$5:$S$44,"<>Пауза") -> 176925 | D35: =SUMIFS(Модель!$AS$5:$AS$44,Модель!$S$5:$S$44,"<>Пауза") -> 158700 | E35: =SUM(Модель!$BG$5:$BG$44) -> 173375 | F35: =E35 -> 173375
B36: Возвратная логистика Ozon | C36: =SUMIFS(Модель!$AH$5:$AH$44,Модель!$S$5:$S$44,"<>Пауза") -> 82202.78 | D36: =SUMIFS(Модель!$AW$5:$AW$44,Модель!$S$5:$S$44,"<>Пауза")-SUMPRODUCT((Модель!$S$5:$S$44<>"Пауза")*Модель!$AL$5:$AL$44)*'Затраты продавца'!$B$9-SUMPRODUCT((Модель!$S$5:$S$44<>"Пауза")*Модель!$AL$5:$AL$44*Модель!$I$5:$I$44)*(1-'Затраты продавца'!$B$10)*Модель!$C$55 -> 76085.74 | E36: =SUM(Модель!$BL$5:$BL$44)-SUMPRODUCT((Модель!$S$5:$S$44="FBS")*Модель!$AL$5:$AL$44)*'Затраты продавца'!$B$9-SUMPRODUCT((Модель!$S$5:$S$44="FBS")*Модель!$AL$5:$AL$44*Модель!$I$5:$I$44)*(1-'Затраты продавца'!$B$10)*Модель!$C$55 -> 80483.08 | F36: =E36 -> 80483.08
B37: Обработка возвратов | C37: =0 -> 0 | D37: =SUMPRODUCT((Модель!$S$5:$S$44<>"Пауза")*Модель!$AL$5:$AL$44)*'Затраты продавца'!$B$9 -> 54700 | E37: =SUMPRODUCT((Модель!$S$5:$S$44="FBS")*Модель!$AL$5:$AL$44)*'Затраты продавца'!$B$9 -> 8700 | F37: ='Fulllog 3PL'!$D$17 -> 5046
B38: Штрафы, списания и прочее | C38: =SUMIFS(Модель!$BN$5:$BN$44,Модель!$S$5:$S$44,"<>Пауза") -> 111684 | D38: =SUMIFS(Модель!$AX$5:$AX$44,Модель!$S$5:$S$44,"<>Пауза")+SUMPRODUCT((Модель!$S$5:$S$44<>"Пауза")*Модель!$AL$5:$AL$44*Модель!$I$5:$I$44)*(1-'Затраты продавца'!$B$10)*Модель!$C$55 -> 212339.25 | E38: =SUM(Модель!$BM$5:$BM$44)+SUMIFS(Модель!$BN$5:$BN$44,Модель!$S$5:$S$44,"FBO")+SUMPRODUCT((Модель!$S$5:$S$44="FBS")*Модель!$AL$5:$AL$44*Модель!$I$5:$I$44)*(1-'Затраты продавца'!$B$10)*Модель!$C$55 -> 130107 | F38: =E38 -> 130107
B39: Итого операционные расходы | C39: =SUM(C27:C38) -> 6045992.3 | D39: =SUM(D27:D38) -> 4674059.8 | E39: =SUM(E27:E38) -> 4826884.9 | F39: =SUM(F27:F38) -> 4701033.2
B40: ФИНАНСОВЫЙ РЕЗУЛЬТАТ
B41: Статья | C41: FBO | D41: FBS | E41: Гибрид | F41: Гибрид с Fulllog (3PL)
B42: Операционная прибыль | C42: =C24-C39 -> 2151647.7 | D42: =D24-D39 -> 2608490.2 | E42: =E24-E39 -> 2938795.1 | F42: =F24-F39 -> 3064646.8
B43: Операционная маржа | C43: =C42/C22 -> 0.14808016 | D43: =D42/D22 -> 0.20257302 | E43: =E42/E22 -> 0.2150125 | F43: =F42/F22 -> 0.22422025
B44: Разница к FBO | C44: =0 -> 0 | D44: =D42-$C$42 -> 456842.47 | E44: =E42-$C$42 -> 787147.43 | F44: =F42-$C$42 -> 912999.13

Sheet Модель
B2: Расчёт экономики по SKU
B4: Источник | C4: Артикул | D4: Товар | E4: Категория | F4: Текущая схема | G4: Выкупы в модели | H4: Цена | I4: Себестоимость | J4: Объём, л | K4: Возвраты | L4: Оборачиваемость, дн. | M4: Комиссия FBO | N4: Комиссия FBS | O4: Прибыль FBO без первой мили | P4: Прибыль FBS без первой мили | Q4: Рекомендация | R4: Ручной выбор | S4: Схема в гибриде | T4: Прибыль выбранной схемы | U4: Отправления FBS | V4: Объём FBS, м³ | X4: FBO: отправления | Y4: FBO: возвраты | Z4: FBO: выручка | AA4: FBO: COGS | AB4: FBO: комиссия | AC4: FBO: эквайринг | AD4: FBO: прямая логистика | AE4: FBO: последняя миля | AF4: FBO: хранение | AG4: FBO: входящая логистика | AH4: FBO: возвратная логистика | AI4: FBS: заказы | AJ4: FBS: отмены | AK4: FBS: отправления | AL4: FBS: возвраты | AM4: FBS: выкупы | AN4: FBS: выручка | AO4: FBS: COGS | AP4: FBS: комиссия | AQ4: FBS: эквайринг | AR4: FBS: прямая логистика | AS4: FBS: последняя миля | AT4: FBS: хранение | AU4: FBS: сборка и упаковка | AV4: FBS: drop-off | AW4: FBS: расходы возвратов | AX4: FBS: штрафы | AY4: FBS: объём, м³ | AZ4: Гибрид: выкупы | BA4: Гибрид: отправления | BB4: Гибрид: выручка | BC4: Гибрид: COGS | BD4: Гибрид: комиссия | BE4: Гибрид: эквайринг | BF4: Гибрид: прямая логистика | BG4: Гибрид: последняя миля | BH4: Гибрид: хранение | BI4: Гибрид: входящая FBO | BJ4: Гибрид: сборка и упаковка | BK4: Гибрид: drop-off | BL4: Гибрид: расходы возвратов | BM4: Гибрид: штрафы | BN4: FBO: списания возвратов | BO4: FBO: нормативный запас, шт. | BP4: FBS: нормативный запас, шт. | BQ4: Гибрид: нормативный запас, шт.
B5: =HYPERLINK("#'SKU'!A2","SKU!2") -> SKU!2 | C5: =SKU!A2 -> SM-0001 | D5: =SKU!B2 -> Кроссовки беговые мужские | E5: =SKU!C2 -> Обувь | F5: =SKU!L2 -> FBO | G5: =SKU!K2*IF(SKU!L2="не представлен",$C$52,1) -> 260 | H5: =SKU!D2 -> 3990 | I5: =SKU!E2 -> 1900 | J5: =SKU!I2 -> 8.316 | K5: =SKU!N2 -> 0.14 | L5: =IF(ISNUMBER(SKU!M2),SKU!M2,$C$53) -> 66.679446 | M5: =VLOOKUP(E5,$B$58:$D$63,2,FALSE()) -> 0.16 | N5: =VLOOKUP(E5,$B$58:$D$63,3,FALSE()) -> 0.15 | O5: =Z5-SUM(AA5:AF5)-AH5-BN5 -> 227204.36 | P5: =AN5-SUM(AO5:AX5) -> 224934.26 | Q5: =IF(MAX(O5,P5)<0,"Пауза",IF(P5>O5,"FBS","FBO")) -> FBO | R5: Авто | S5: =IF(R5="Авто",Q5,R5) -> FBO | T5: =IF(S5="FBO",O5,IF(S5="FBS",P5,0)) -> 227204.36 | U5: =IF(S5="FBS",AK5,0) -> 0 | V5: =IF(S5="FBS",AY5,0) -> 0 | X5: =ROUNDUP(G5/(1-K5),0) -> 303 | Y5: =X5-G5 -> 43 | Z5: =G5*H5 -> 1037400 | AA5: =G5*I5 -> 494000 | AB5: =Z5*M5 -> 165984 | AC5: =Z5*Тарифы!$B$32 -> 15561 | AD5: =X5*(Тарифы!$B$18+MAX(0,J5-5)*Тарифы!$B$19) -> 34287.48 | AE5: =X5*Тарифы!$B$20 -> 7575 | AF5: =BO5*J5*$C$48*IF(E5="Крупногабарит",$C$68,Тарифы!$B$21) -> 75667.284 | AG5: =X5*J5*'Затраты продавца'!$B$12 -> 6299.37 | AH5: =Y5*(Тарифы!$B$18+MAX(0,J5-5)*Тарифы!$B$19)*Тарифы!$B$22 -> 4865.88 | AI5: =ROUNDUP(G5/(1-MIN(0.99,MAX(0,K5+$C$51)))*$C$49,0) -> 303 | AJ5: =ROUNDUP(AI5*$C$50,0) -> 31 | AK5: =AI5-AJ5 -> 272 | AL5: =ROUNDUP(AK5*MIN(0.99,MAX(0,K5+$C$51)),0) -> 39 | AM5: =AK5-AL5 -> 233 | AN5: =AM5*H5 -> 929670 | AO5: =AM5*I5 -> 442700 | AP5: =AN5*N5 -> 139450.5 | AQ5: =AN5*Тарифы!$B$32 -> 13945.05 | AR5: =AK5*(Тарифы!$B$25+MAX(0,J5-5)*Тарифы!$B$26) -> 30779.52 | AS5: =AK5*Тарифы!$B$27 -> 6800 | AT5: =BP5*J5*$C$48*'Затраты продавца'!$B$5 -> 25222.428 | AU5: =AK5*('Затраты продавца'!$B$6+'Затраты продавца'!$B$7) -> 19040 | AV5: =AK5*Тарифы!$B$24 -> 2720 | AW5: =AL5*((Тарифы!$B$25+MAX(0,J5-5)*Тарифы!$B$26)*Тарифы!$B$28+'Затраты продавца'!$B$9+(1-'Затраты продавца'!$B$10)*I5*$C$55) -> 19428.24 | AX5: =AJ5*Тарифы!$B$29 -> 4650 | AY5: =AK5*J5/1000 -> 2.261952 | AZ5: =IF(S5="FBO",G5,IF(S5="FBS",AM5,0)) -> 260 | BA5: =IF(S5="FBO",X5,IF(S5="FBS",AK5,0)) -> 303 | BB5: =IF(S5="FBO",Z5,IF(S5="FBS",AN5,0)) -> 1037400 | BC5: =IF(S5="FBO",AA5,IF(S5="FBS",AO5,0)) -> 494000 | BD5: =IF(S5="FBO",AB5,IF(S5="FBS",AP5,0)) -> 165984 | BE5: =IF(S5="FBO",AC5,IF(S5="FBS",AQ5,0)) -> 15561 | BF5: =IF(S5="FBO",AD5,IF(S5="FBS",AR5,0)) -> 34287.48 | BG5: =IF(S5="FBO",AE5,IF(S5="FBS",AS5,0)) -> 7575 | BH5: =IF(S5="FBO",AF5,IF(S5="FBS",AT5,0)) -> 75667.284 | BI5: =IF(S5="FBO",AG5,0) -> 6299.37 | BJ5: =IF(S5="FBS",AU5,0) -> 0 | BK5: =IF(S5="FBS",AV5,0) -> 0 | BL5: =IF(S5="FBO",AH5,IF(S5="FBS",AW5,0)) -> 4865.88 | BM5: =IF(S5="FBS",AX5,0) -> 0 | BN5: =Y5*I5*(1-'Затраты продавца'!$B$10)*$C$55 -> 12255 | BO5: =ROUNDUP(X5*L5/$C$48,0) -> 674 | BP5: =ROUNDUP(AI5*L5*$C$54/$C$48,0) -> 674 | BQ5: =IF(S5="FBO",BO5,IF(S5="FBS",BP5,0)) -> 674
B6: =HYPERLINK("#'SKU'!A3","SKU!3") -> SKU!3 | C6: =SKU!A3 -> SM-0002 | D6: =SKU!B3 -> Кроссовки трейловые | E6: =SKU!C3 -> Обувь | F6: =SKU!L3 -> FBO | G6: =SKU!K3*IF(SKU!L3="не представлен",$C$52,1) -> 180 | H6: =SKU!D3 -> 5490 | I6: =SKU!E3 -> 2600 | J6: =SKU!I3 -> 9.724 | K6: =SKU!N3 -> 0.15 | L6: =IF(ISNUMBER(SKU!M3),SKU!M3,$C$53) -> 67.064723 | M6: =VLOOKUP(E6,$B$58:$D$63,2,FALSE()) -> 0.16 | N6: =VLOOKUP(E6,$B$58:$D$63,3,FALSE()) -> 0.15 | O6: =Z6-SUM(AA6:AF6)-AH6-BN6 -> 236214.56 | P6: =AN6-SUM(AO6:AX6) -> 233381.3 | Q6: =IF(MAX(O6,P6)<0,"Пауза",IF(P6>O6,"FBS","FBO")) -> FBO | R6: Авто | S6: =IF(R6="Авто",Q6,R6) -> FBO | T6: =IF(S6="FBO",O6,IF(S6="FBS",P6,0)) -> 236214.56 | U6: =IF(S6="FBS",AK6,0) -> 0 | V6: =IF(S6="FBS",AY6,0) -> 0 | X6: =ROUNDUP(G6/(1-K6),0) -> 212 | Y6: =X6-G6 -> 32 | Z6: =G6*H6 -> 988200 | AA6: =G6*I6 -> 468000 | AB6: =Z6*M6 -> 158112 | AC6: =Z6*Тарифы!$B$32 -> 14823 | AD6: =X6*(Тарифы!$B$18+MAX(0,J6-5)*Тарифы!$B$19) -> 26974.88 | AE6: =X6*Тарифы!$B$20 -> 5300 | AF6: =BO6*J6*$C$48*IF(E6="Крупногабарит",$C$68,Тарифы!$B$21) -> 62223.876 | AG6: =X6*J6*'Затраты продавца'!$B$12 -> 5153.72 | AH6: =Y6*(Тарифы!$B$18+MAX(0,J6-5)*Тарифы!$B$19)*Тарифы!$B$22 -> 4071.68 | AI6: =ROUNDUP(G6/(1-MIN(0.99,MAX(0,K6+$C$51)))*$C$49,0) -> 212 | AJ6: =ROUNDUP(AI6*$C$50,0) -> 22 | AK6: =AI6-AJ6 -> 190 | AL6: =ROUNDUP(AK6*MIN(0.99,MAX(0,K6+$C$51)),0) -> 29 | AM6: =AK6-AL6 -> 161 | AN6: =AM6*H6 -> 883890 | AO6: =AM6*I6 -> 418600 | AP6: =AN6*N6 -> 132583.5 | AQ6: =AN6*Тарифы!$B$32 -> 13258.35 | AR6: =AK6*(Тарифы!$B$25+MAX(0,J6-5)*Тарифы!$B$26) -> 24175.6 | AS6: =AK6*Тарифы!$B$27 -> 4750 | AT6: =BP6*J6*$C$48*'Затраты продавца'!$B$5 -> 20741.292 | AU6: =AK6*('Затраты продавца'!$B$6+'Затраты продавца'!$B$7) -> 13300 | AV6: =AK6*Тарифы!$B$24 -> 1900 | AW6: =AL6*((Тарифы!$B$25+MAX(0,J6-5)*Тарифы!$B$26)*Тарифы!$B$28+'Затраты продавца'!$B$9+(1-'Затраты продавца'!$B$10)*I6*$C$55) -> 17899.96 | AX6: =AJ6*Тарифы!$B$29 -> 3300 | AY6: =AK6*J6/1000 -> 1.84756 | AZ6: =IF(S6="FBO",G6,IF(S6="FBS",AM6,0)) -> 180 | BA6: =IF(S6="FBO",X6,IF(S6="FBS",AK6,0)) -> 212 | BB6: =IF(S6="FBO",Z6,IF(S6="FBS",AN6,0)) -> 988200 | BC6: =IF(S6="FBO",AA6,IF(S6="FBS",AO6,0)) -> 468000 | BD6: =IF(S6="FBO",AB6,IF(S6="FBS",AP6,0)) -> 158112 | BE6: =IF(S6="FBO",AC6,IF(S6="FBS",AQ6,0)) -> 14823 | BF6: =IF(S6="FBO",AD6,IF(S6="FBS",AR6,0)) -> 26974.88 | BG6: =IF(S6="FBO",AE6,IF(S6="FBS",AS6,0)) -> 5300 | BH6: =IF(S6="FBO",AF6,IF(S6="FBS",AT6,0)) -> 62223.876 | BI6: =IF(S6="FBO",AG6,0) -> 5153.72 | BJ6: =IF(S6="FBS",AU6,0) -> 0 | BK6: =IF(S6="FBS",AV6,0) -> 0 | BL6: =IF(S6="FBO",AH6,IF(S6="FBS",AW6,0)) -> 4071.68 | BM6: =IF(S6="FBS",AX6,0) -> 0 | BN6: =Y6*I6*(1-'Затраты продавца'!$B$10)*$C$55 -> 12480 | BO6: =ROUNDUP(X6*L6/$C$48,0) -> 474 | BP6: =ROUNDUP(AI6*L6*$C$54/$C$48,0) -> 474 | BQ6: =IF(S6="FBO",BO6,IF(S6="FBS",BP6,0)) -> 474
B7: =HYPERLINK("#'SKU'!A4","SKU!4") -> SKU!4 | C7: =SKU!A4 -> SM-0003 | D7: =SKU!B4 -> Кеды классические | E7: =SKU!C4 -> Обувь | F7: =SKU!L4 -> FBO | G7: =SKU!K4*IF(SKU!L4="не представлен",$C$52,1) -> 340 | H7: =SKU!D4 -> 2490 | I7: =SKU!E4 -> 1050 | J7: =SKU!I4 -> 7.04 | K7: =SKU!N4 -> 0.12 | L7: =IF(ISNUMBER(SKU!M4),SKU!M4,$C$53) -> 48.031221 | M7: =VLOOKUP(E7,$B$58:$D$63,2,FALSE()) -> 0.16 | N7: =VLOOKUP(E7,$B$58:$D$63,3,FALSE()) -> 0.15 | O7: =Z7-SUM(AA7:AF7)-AH7-BN7 -> 221869.1 | P7: =AN7-SUM(AO7:AX7) -> 202917.3 | Q7: =IF(MAX(O7,P7)<0,"Пауза",IF(P7>O7,"FBS","FBO")) -> FBO | R7: Авто | S7: =IF(R7="Авто",Q7,R7) -> FBO | T7: =IF(S7="FBO",O7,IF(S7="FBS",P7,0)) -> 221869.1 | U7: =IF(S7="FBS",AK7,0) -> 0 | V7: =IF(S7="FBS",AY7,0) -> 0 | X7: =ROUNDUP(G7/(1-K7),0) -> 387 | Y7: =X7-G7 -> 47 | Z7: =G7*H7 -> 846600 | AA7: =G7*I7 -> 357000 | AB7: =Z7*M7 -> 135456 | AC7: =Z7*Тарифы!$B$32 -> 12699 | AD7: =X7*(Тарифы!$B$18+MAX(0,J7-5)*Тарифы!$B$19) -> 38854.8 | AE7: =X7*Тарифы!$B$20 -> 9675 | AF7: =BO7*J7*$C$48*IF(E7="Крупногабарит",$C$68,Тарифы!$B$21) -> 58924.8 | AG7: =X7*J7*'Затраты продавца'!$B$12 -> 6811.2 | AH7: =Y7*(Тарифы!$B$18+MAX(0,J7-5)*Тарифы!$B$19)*Тарифы!$B$22 -> 4718.8 | AI7: =ROUNDUP(G7/(1-MIN(0.99,MAX(0,K7+$C$51)))*$C$49,0) -> 387 | AJ7: =ROUNDUP(AI7*$C$50,0) -> 39 | AK7: =AI7-AJ7 -> 348 | AL7: =ROUNDUP(AK7*MIN(0.99,MAX(0,K7+$C$51)),0) -> 42 | AM7: =AK7-AL7 -> 306 | AN7: =AM7*H7 -> 761940 | AO7: =AM7*I7 -> 321300 | AP7: =AN7*N7 -> 114291 | AQ7: =AN7*Тарифы!$B$32 -> 11429.1 | AR7: =AK7*(Тарифы!$B$25+MAX(0,J7-5)*Тарифы!$B$26) -> 34939.2 | AS7: =AK7*Тарифы!$B$27 -> 8700 | AT7: =BP7*J7*$C$48*'Затраты продавца'!$B$5 -> 19641.6 | AU7: =AK7*('Затраты продавца'!$B$6+'Затраты продавца'!$B$7) -> 24360 | AV7: =AK7*Тарифы!$B$24 -> 3480 | AW7: =AL7*((Тарифы!$B$25+MAX(0,J7-5)*Тарифы!$B$26)*Тарифы!$B$28+'Затраты продавца'!$B$9+(1-'Затраты продавца'!$B$10)*I7*$C$55) -> 15031.8 | AX7: =AJ7*Тарифы!$B$29 -> 5850 | AY7: =AK7*J7/1000 -> 2.44992 | AZ7: =IF(S7="FBO",G7,IF(S7="FBS",AM7,0)) -> 340 | BA7: =IF(S7="FBO",X7,IF(S7="FBS",AK7,0)) -> 387 | BB7: =IF(S7="FBO",Z7,IF(S7="FBS",AN7,0)) -> 846600 | BC7: =IF(S7="FBO",AA7,IF(S7="FBS",AO7,0)) -> 357000 | BD7: =IF(S7="FBO",AB7,IF(S7="FBS",AP7,0)) -> 135456 | BE7: =IF(S7="FBO",AC7,IF(S7="FBS",AQ7,0)) -> 12699 | BF7: =IF(S7="FBO",AD7,IF(S7="FBS",AR7,0)) -> 38854.8 | BG7: =IF(S7="FBO",AE7,IF(S7="FBS",AS7,0)) -> 9675 | BH7: =IF(S7="FBO",AF7,IF(S7="FBS",AT7,0)) -> 58924.8 | BI7: =IF(S7="FBO",AG7,0) -> 6811.2 | BJ7: =IF(S7="FBS",AU7,0) -> 0 | BK7: =IF(S7="FBS",AV7,0) -> 0 | BL7: =IF(S7="FBO",AH7,IF(S7="FBS",AW7,0)) -> 4718.8 | BM7: =IF(S7="FBS",AX7,0) -> 0 | BN7: =Y7*I7*(1-'Затраты продавца'!$B$10)*$C$55 -> 7402.5 | BO7: =ROUNDUP(X7*L7/$C$48,0) -> 620 | BP7: =ROUNDUP(AI7*L7*$C$54/$C$48,0) -> 620 | BQ7: =IF(S7="FBO",BO7,IF(S7="FBS",BP7,0)) -> 620
B8: =HYPERLINK("#'SKU'!A5","SKU!5") -> SKU!5 | C8: =SKU!A5 -> SM-0004 | D8: =SKU!B5 -> Ботинки треккинговые | E8: =SKU!C5 -> Обувь | F8: =SKU!L5 -> FBO | G8: =SKU!K5*IF(SKU!L5="не представлен",$C$52,1) -> 85 | H8: =SKU!D5 -> 7990 | I8: =SKU!E5 -> 3800 | J8: =SKU!I5 -> 11.76 | K8: =SKU!N5 -> 0.16 | L8: =IF(ISNUMBER(SKU!M5),SKU!M5,$C$53) -> 73.154068 | M8: =VLOOKUP(E8,$B$58:$D$63,2,FALSE()) -> 0.16 | N8: =VLOOKUP(E8,$B$58:$D$63,3,FALSE()) -> 0.15 | O8: =Z8-SUM(AA8:AF8)-AH8-BN8 -> 167963.11 | P8: =AN8-SUM(AO8:AX8) -> 168167.72 | Q8: =IF(MAX(O8,P8)<0,"Пауза",IF(P8>O8,"FBS","FBO")) -> FBS | R8: Авто | S8: =IF(R8="Авто",Q8,R8) -> FBS | T8: =IF(S8="FBO",O8,IF(S8="FBS",P8,0)) -> 168167.72 | U8: =IF(S8="FBS",AK8,0) -> 91 | V8: =IF(S8="FBS",AY8,0) -> 1.07016 | X8: =ROUNDUP(G8/(1-K8),0) -> 102 | Y8: =X8-G8 -> 17 | Z8: =G8*H8 -> 679150 | AA8: =G8*I8 -> 323000 | AB8: =Z8*M8 -> 108664 | AC8: =Z8*Тарифы!$B$32 -> 10187.25 | AD8: =X8*(Тарифы!$B$18+MAX(0,J8-5)*Тарифы!$B$19) -> 15055.2 | AE8: =X8*Тарифы!$B$20 -> 2550 | AF8: =BO8*J8*$C$48*IF(E8="Крупногабарит",$C$68,Тарифы!$B$21) -> 39531.24 | AG8: =X8*J8*'Затраты продавца'!$B$12 -> 2998.8 | AH8: =Y8*(Тарифы!$B$18+MAX(0,J8-5)*Тарифы!$B$19)*Тарифы!$B$22 -> 2509.2 | AI8: =ROUNDUP(G8/(1-MIN(0.99,MAX(0,K8+$C$51)))*$C$49,0) -> 102 | AJ8: =ROUNDUP(AI8*$C$50,0) -> 11 | AK8: =AI8-AJ8 -> 91 | AL8: =ROUNDUP(AK8*MIN(0.99,MAX(0,K8+$C$51)),0) -> 15 | AM8: =AK8-AL8 -> 76 | AN8: =AM8*H8 -> 607240 | AO8: =AM8*I8 -> 288800 | AP8: =AN8*N8 -> 91086 | AQ8: =AN8*Тарифы!$B$32 -> 9108.6 | AR8: =AK8*(Тарифы!$B$25+MAX(0,J8-5)*Тарифы!$B$26) -> 13431.6 | AS8: =AK8*Тарифы!$B$27 -> 2275 | AT8: =BP8*J8*$C$48*'Затраты продавца'!$B$5 -> 13177.08 | AU8: =AK8*('Затраты продавца'!$B$6+'Затраты продавца'!$B$7) -> 6370 | AV8: =AK8*Тарифы!$B$24 -> 910 | AW8: =AL8*((Тарифы!$B$25+MAX(0,J8-5)*Тарифы!$B$26)*Тарифы!$B$28+'Затраты продавца'!$B$9+(1-'Затраты продавца'!$B$10)*I8*$C$55) -> 12264 | AX8: =AJ8*Тарифы!$B$29 -> 1650 | AY8: =AK8*J8/1000 -> 1.07016 | AZ8: =IF(S8="FBO",G8,IF(S8="FBS",AM8,0)) -> 76 | BA8: =IF(S8="FBO",X8,IF(S8="FBS",AK8,0)) -> 91 | BB8: =IF(S8="FBO",Z8,IF(S8="FBS",AN8,0)) -> 607240 | BC8: =IF(S8="FBO",AA8,IF(S8="FBS",AO8,0)) -> 288800 | BD8: =IF(S8="FBO",AB8,IF(S8="FBS",AP8,0)) -> 91086 | BE8: =IF(S8="FBO",AC8,IF(S8="FBS",AQ8,0)) -> 9108.6 | BF8: =IF(S8="FBO",AD8,IF(S8="FBS",AR8,0)) -> 13431.6 | BG8: =IF(S8="FBO",AE8,IF(S8="FBS",AS8,0)) -> 2275 | BH8: =IF(S8="FBO",AF8,IF(S8="FBS",AT8,0)) -> 13177.08 | BI8: =IF(S8="FBO",AG8,0) -> 0 | BJ8: =IF(S8="FBS",AU8,0) -> 6370 | BK8: =IF(S8="FBS",AV8,0) -> 910 | BL8: =IF(S8="FBO",AH8,IF(S8="FBS",AW8,0)) -> 12264 | BM8: =IF(S8="FBS",AX8,0) -> 1650 | BN8: =Y8*I8*(1-'Затраты продавца'!$B$10)*$C$55 -> 9690 | BO8: =ROUNDUP(X8*L8/$C$48,0) -> 249 | BP8: =ROUNDUP(AI8*L8*$C$54/$C$48,0) -> 249 | BQ8: =IF(S8="FBO",BO8,IF(S8="FBS",BP8,0)) -> 249
B9: =HYPERLINK("#'SKU'!A6","SKU!6") -> SKU!6 | C9: =SKU!A6 -> SM-0005 | D9: =SKU!B6 -> Сланцы пляжные | E9: =SKU!C6 -> Обувь | F9: =SKU!L6 -> FBO | G9: =SKU!K6*IF(SKU!L6="не представлен",$C$52,1) -> 480 | H9: =SKU!D6 -> 890 | I9: =SKU!E6 -> 290 | J9: =SKU!I6 -> 3.36 | K9: =SKU!N6 -> 0.06 | L9: =IF(ISNUMBER(SKU!M6),SKU!M6,$C$53) -> 79.611473 | M9: =VLOOKUP(E9,$B$58:$D$63,2,FALSE()) -> 0.16 | N9: =VLOOKUP(E9,$B$58:$D$63,3,FALSE()) -> 0.15 | O9: =Z9-SUM(AA9:AF9)-AH9-BN9 -> 94202.98 | P9: =AN9-SUM(AO9:AX9) -> 75816.81 | Q9: =IF(MAX(O9,P9)<0,"Пауза",IF(P9>O9,"FBS","FBO")) -> FBO | R9: Авто | S9: =IF(R9="Авто",Q9,R9) -> FBO | T9: =IF(S9="FBO",O9,IF(S9="FBS",P9,0)) -> 94202.98 | U9: =IF(S9="FBS",AK9,0) -> 0 | V9: =IF(S9="FBS",AY9,0) -> 0 | X9: =ROUNDUP(G9/(1-K9),0) -> 511 | Y9: =X9-G9 -> 31 | Z9: =G9*H9 -> 427200 | AA9: =G9*I9 -> 139200 | AB9: =Z9*M9 -> 68352 | AC9: =Z9*Тарифы!$B$32 -> 6408 | AD9: =X9*(Тарифы!$B$18+MAX(0,J9-5)*Тарифы!$B$19) -> 40880 | AE9: =X9*Тарифы!$B$20 -> 12775 | AF9: =BO9*J9*$C$48*IF(E9="Крупногабарит",$C$68,Тарифы!$B$21) -> 61553.52 | AG9: =X9*J9*'Затраты продавца'!$B$12 -> 4292.4 | AH9: =Y9*(Тарифы!$B$18+MAX(0,J9-5)*Тарифы!$B$19)*Тарифы!$B$22 -> 2480 | AI9: =ROUNDUP(G9/(1-MIN(0.99,MAX(0,K9+$C$51)))*$C$49,0) -> 511 | AJ9: =ROUNDUP(AI9*$C$50,0) -> 52 | AK9: =AI9-AJ9 -> 459 | AL9: =ROUNDUP(AK9*MIN(0.99,MAX(0,K9+$C$51)),0) -> 28 | AM9: =AK9-AL9 -> 431 | AN9: =AM9*H9 -> 383590 | AO9: =AM9*I9 -> 124990 | AP9: =AN9*N9 -> 57538.5 | AQ9: =AN9*Тарифы!$B$32 -> 5753.85 | AR9: =AK9*(Тарифы!$B$25+MAX(0,J9-5)*Тарифы!$B$26) -> 36720 | AS9: =AK9*Тарифы!$B$27 -> 11475 | AT9: =BP9*J9*$C$48*'Затраты продавца'!$B$5 -> 20517.84 | AU9: =AK9*('Затраты продавца'!$B$6+'Затраты продавца'!$B$7) -> 32130 | AV9: =AK9*Тарифы!$B$24 -> 4590 | AW9: =AL9*((Тарифы!$B$25+MAX(0,J9-5)*Тарифы!$B$26)*Тарифы!$B$28+'Затраты продавца'!$B$9+(1-'Затраты продавца'!$B$10)*I9*$C$55) -> 6258 | AX9: =AJ9*Тарифы!$B$29 -> 7800 | AY9: =AK9*J9/1000 -> 1.54224 | AZ9: =IF(S9="FBO",G9,IF(S9="FBS",AM9,0)) -> 480 | BA9: =IF(S9="FBO",X9,IF(S9="FBS",AK9,0)) -> 511 | BB9: =IF(S9="FBO",Z9,IF(S9="FBS",AN9,0)) -> 427200 | BC9: =IF(S9="FBO",AA9,IF(S9="FBS",AO9,0)) -> 139200 | BD9: =IF(S9="FBO",AB9,IF(S9="FBS",AP9,0)) -> 68352 | BE9: =IF(S9="FBO",AC9,IF(S9="FBS",AQ9,0)) -> 6408 | BF9: =IF(S9="FBO",AD9,IF(S9="FBS",AR9,0)) -> 40880 | BG9: =IF(S9="FBO",AE9,IF(S9="FBS",AS9,0)) -> 12775 | BH9: =IF(S9="FBO",AF9,IF(S9="FBS",AT9,0)) -> 61553.52 | BI9: =IF(S9="FBO",AG9,0) -> 4292.4 | BJ9: =IF(S9="FBS",AU9,0) -> 0 | BK9: =IF(S9="FBS",AV9,0) -> 0 | BL9: =IF(S9="FBO",AH9,IF(S9="FBS",AW9,0)) -> 2480 | BM9: =IF(S9="FBS",AX9,0) -> 0 | BN9: =Y9*I9*(1-'Затраты продавца'!$B$10)*$C$55 -> 1348.5 | BO9: =ROUNDUP(X9*L9/$C$48,0) -> 1357 | BP9: =ROUNDUP(AI9*L9*$C$54/$C$48,0) -> 1357 | BQ9: =IF(S9="FBO",BO9,IF(S9="FBS",BP9,0)) -> 1357
B10: =HYPERLINK("#'SKU'!A7","SKU!7") -> SKU!7 | C10: =SKU!A7 -> SM-0006 | D10: =SKU!B7 -> Футболка тренировочная | E10: =SKU!C7 -> Одежда | F10: =SKU!L7 -> FBO | G10: =SKU!K7*IF(SKU!L7="не представлен",$C$52,1) -> 620 | H10: =SKU!D7 -> 990 | I10: =SKU!E7 -> 340 | J10: =SKU!I7 -> 1.98 | K10: =SKU!N7 -> 0.15 | L10: =IF(ISNUMBER(SKU!M7),SKU!M7,$C$53) -> 77.881051 | M10: =VLOOKUP(E10,$B$58:$D$63,2,FALSE()) -> 0.17 | N10: =VLOOKUP(E10,$B$58:$D$63,3,FALSE()) -> 0.16 | O10: =Z10-SUM(AA10:AF10)-AH10-BN10 -> 147706.92 | P10: =AN10-SUM(AO10:AX10) -> 93769.14 | Q10: =IF(MAX(O10,P10)<0,"Пауза",IF(P10>O10,"FBS","FBO")) -> FBO | R10: Авто | S10: =IF(R10="Авто",Q10,R10) -> FBO | T10: =IF(S10="FBO",O10,IF(S10="FBS",P10,0)) -> 147706.92 | U10: =IF(S10="FBS",AK10,0) -> 0 | V10: =IF(S10="FBS",AY10,0) -> 0 | X10: =ROUNDUP(G10/(1-K10),0) -> 730 | Y10: =X10-G10 -> 110 | Z10: =G10*H10 -> 613800 | AA10: =G10*I10 -> 210800 | AB10: =Z10*M10 -> 104346 | AC10: =Z10*Тарифы!$B$32 -> 9207 | AD10: =X10*(Тарифы!$B$18+MAX(0,J10-5)*Тарифы!$B$19) -> 58400 | AE10: =X10*Тарифы!$B$20 -> 18250 | AF10: =BO10*J10*$C$48*IF(E10="Крупногабарит",$C$68,Тарифы!$B$21) -> 50680.08 | AG10: =X10*J10*'Затраты продавца'!$B$12 -> 3613.5 | AH10: =Y10*(Тарифы!$B$18+MAX(0,J10-5)*Тарифы!$B$19)*Тарифы!$B$22 -> 8800 | AI10: =ROUNDUP(G10/(1-MIN(0.99,MAX(0,K10+$C$51)))*$C$49,0) -> 730 | AJ10: =ROUNDUP(AI10*$C$50,0) -> 73 | AK10: =AI10-AJ10 -> 657 | AL10: =ROUNDUP(AK10*MIN(0.99,MAX(0,K10+$C$51)),0) -> 99 | AM10: =AK10-AL10 -> 558 | AN10: =AM10*H10 -> 552420 | AO10: =AM10*I10 -> 189720 | AP10: =AN10*N10 -> 88387.2 | AQ10: =AN10*Тарифы!$B$32 -> 8286.3 | AR10: =AK10*(Тарифы!$B$25+MAX(0,J10-5)*Тарифы!$B$26) -> 52560 | AS10: =AK10*Тарифы!$B$27 -> 16425 | AT10: =BP10*J10*$C$48*'Затраты продавца'!$B$5 -> 16893.36 | AU10: =AK10*('Затраты продавца'!$B$6+'Затраты продавца'!$B$7) -> 45990 | AV10: =AK10*Тарифы!$B$24 -> 6570 | AW10: =AL10*((Тарифы!$B$25+MAX(0,J10-5)*Тарифы!$B$26)*Тарифы!$B$28+'Затраты продавца'!$B$9+(1-'Затраты продавца'!$B$10)*I10*$C$55) -> 22869 | AX10: =AJ10*Тарифы!$B$29 -> 10950 | AY10: =AK10*J10/1000 -> 1.30086 | AZ10: =IF(S10="FBO",G10,IF(S10="FBS",AM10,0)) -> 620 | BA10: =IF(S10="FBO",X10,IF(S10="FBS",AK10,0)) -> 730 | BB10: =IF(S10="FBO",Z10,IF(S10="FBS",AN10,0)) -> 613800 | BC10: =IF(S10="FBO",AA10,IF(S10="FBS",AO10,0)) -> 210800 | BD10: =IF(S10="FBO",AB10,IF(S10="FBS",AP10,0)) -> 104346 | BE10: =IF(S10="FBO",AC10,IF(S10="FBS",AQ10,0)) -> 9207 | BF10: =IF(S10="FBO",AD10,IF(S10="FBS",AR10,0)) -> 58400 | BG10: =IF(S10="FBO",AE10,IF(S10="FBS",AS10,0)) -> 18250 | BH10: =IF(S10="FBO",AF10,IF(S10="FBS",AT10,0)) -> 50680.08 | BI10: =IF(S10="FBO",AG10,0) -> 3613.5 | BJ10: =IF(S10="FBS",AU10,0) -> 0 | BK10: =IF(S10="FBS",AV10,0) -> 0 | BL10: =IF(S10="FBO",AH10,IF(S10="FBS",AW10,0)) -> 8800 | BM10: =IF(S10="FBS",AX10,0) -> 0 | BN10: =Y10*I10*(1-'Затраты продавца'!$B$10)*$C$55 -> 5610 | BO10: =ROUNDUP(X10*L10/$C$48,0) -> 1896 | BP10: =ROUNDUP(AI10*L10*$C$54/$C$48,0) -> 1896 | BQ10: =IF(S10="FBO",BO10,IF(S10="FBS",BP10,0)) -> 1896
B11: =HYPERLINK("#'SKU'!A8","SKU!8") -> SKU!8 | C11: =SKU!A8 -> SM-0007 | D11: =SKU!B8 -> Шорты беговые | E11: =SKU!C8 -> Одежда | F11: =SKU!L8 -> FBO | G11: =SKU!K8*IF(SKU!L8="не представлен",$C$52,1) -> 380 | H11: =SKU!D8 -> 1290 | I11: =SKU!E8 -> 430 | J11: =SKU!I8 -> 2.24 | K11: =SKU!N8 -> 0.14 | L11: =IF(ISNUMBER(SKU!M8),SKU!M8,$C$53) -> 82.191663 | M11: =VLOOKUP(E11,$B$58:$D$63,2,FALSE()) -> 0.17 | N11: =VLOOKUP(E11,$B$58:$D$63,3,FALSE()) -> 0.16 | O11: =Z11-SUM(AA11:AF11)-AH11-BN11 -> 144123.36 | P11: =AN11-SUM(AO11:AX11) -> 110185.37 | Q11: =IF(MAX(O11,P11)<0,"Пауза",IF(P11>O11,"FBS","FBO")) -> FBO | R11: Авто | S11: =IF(R11="Авто",Q11,R11) -> FBO | T11: =IF(S11="FBO",O11,IF(S11="FBS",P11,0)) -> 144123.36 | U11: =IF(S11="FBS",AK11,0) -> 0 | V11: =IF(S11="FBS",AY11,0) -> 0 | X11: =ROUNDUP(G11/(1-K11),0) -> 442 | Y11: =X11-G11 -> 62 | Z11: =G11*H11 -> 490200 | AA11: =G11*I11 -> 163400 | AB11: =Z11*M11 -> 83334 | AC11: =Z11*Тарифы!$B$32 -> 7353 | AD11: =X11*(Тарифы!$B$18+MAX(0,J11-5)*Тарифы!$B$19) -> 35360 | AE11: =X11*Тарифы!$B$20 -> 11050 | AF11: =BO11*J11*$C$48*IF(E11="Крупногабарит",$C$68,Тарифы!$B$21) -> 36620.64 | AG11: =X11*J11*'Затраты продавца'!$B$12 -> 2475.2 | AH11: =Y11*(Тарифы!$B$18+MAX(0,J11-5)*Тарифы!$B$19)*Тарифы!$B$22 -> 4960 | AI11: =ROUNDUP(G11/(1-MIN(0.99,MAX(0,K11+$C$51)))*$C$49,0) -> 442 | AJ11: =ROUNDUP(AI11*$C$50,0) -> 45 | AK11: =AI11-AJ11 -> 397 | AL11: =ROUNDUP(AK11*MIN(0.99,MAX(0,K11+$C$51)),0) -> 56 | AM11: =AK11-AL11 -> 341 | AN11: =AM11*H11 -> 439890 | AO11: =AM11*I11 -> 146630 | AP11: =AN11*N11 -> 70382.4 | AQ11: =AN11*Тарифы!$B$32 -> 6598.35 | AR11: =AK11*(Тарифы!$B$25+MAX(0,J11-5)*Тарифы!$B$26) -> 31760 | AS11: =AK11*Тарифы!$B$27 -> 9925 | AT11: =BP11*J11*$C$48*'Затраты продавца'!$B$5 -> 12206.88 | AU11: =AK11*('Затраты продавца'!$B$6+'Затраты продавца'!$B$7) -> 27790 | AV11: =AK11*Тарифы!$B$24 -> 3970 | AW11: =AL11*((Тарифы!$B$25+MAX(0,J11-5)*Тарифы!$B$26)*Тарифы!$B$28+'Затраты продавца'!$B$9+(1-'Затраты продавца'!$B$10)*I11*$C$55) -> 13692 | AX11: =AJ11*Тарифы!$B$29 -> 6750 | AY11: =AK11*J11/1000 -> 0.88928 | AZ11: =IF(S11="FBO",G11,IF(S11="FBS",AM11,0)) -> 380 | BA11: =IF(S11="FBO",X11,IF(S11="FBS",AK11,0)) -> 442 | BB11: =IF(S11="FBO",Z11,IF(S11="FBS",AN11,0)) -> 490200 | BC11: =IF(S11="FBO",AA11,IF(S11="FBS",AO11,0)) -> 163400 | BD11: =IF(S11="FBO",AB11,IF(S11="FBS",AP11,0)) -> 83334 | BE11: =IF(S11="FBO",AC11,IF(S11="FBS",AQ11,0)) -> 7353 | BF11: =IF(S11="FBO",AD11,IF(S11="FBS",AR11,0)) -> 35360 | BG11: =IF(S11="FBO",AE11,IF(S11="FBS",AS11,0)) -> 11050 | BH11: =IF(S11="FBO",AF11,IF(S11="FBS",AT11,0)) -> 36620.64 | BI11: =IF(S11="FBO",AG11,0) -> 2475.2 | BJ11: =IF(S11="FBS",AU11,0) -> 0 | BK11: =IF(S11="FBS",AV11,0) -> 0 | BL11: =IF(S11="FBO",AH11,IF(S11="FBS",AW11,0)) -> 4960 | BM11: =IF(S11="FBS",AX11,0) -> 0 | BN11: =Y11*I11*(1-'Затраты продавца'!$B$10)*$C$55 -> 3999 | BO11: =ROUNDUP(X11*L11/$C$48,0) -> 1211 | BP11: =ROUNDUP(AI11*L11*$C$54/$C$48,0) -> 1211 | BQ11: =IF(S11="FBO",BO11,IF(S11="FBS",BP11,0)) -> 1211
B12: =HYPERLINK("#'SKU'!A9","SKU!9") -> SKU!9 | C12: =SKU!A9 -> SM-0008 | D12: =SKU!B9 -> Ветровка для бега | E12: =SKU!C9 -> Одежда | F12: =SKU!L9 -> FBO | G12: =SKU!K9*IF(SKU!L9="не представлен",$C$52,1) -> 150 | H12: =SKU!D9 -> 3490 | I12: =SKU!E9 -> 1400 | J12: =SKU!I9 -> 5.25 | K12: =SKU!N9 -> 0.17 | L12: =IF(ISNUMBER(SKU!M9),SKU!M9,$C$53) -> 79.712035 | M12: =VLOOKUP(E12,$B$58:$D$63,2,FALSE()) -> 0.17 | N12: =VLOOKUP(E12,$B$58:$D$63,3,FALSE()) -> 0.16 | O12: =Z12-SUM(AA12:AF12)-AH12-BN12 -> 154036.62 | P12: =AN12-SUM(AO12:AX12) -> 142640.88 | Q12: =IF(MAX(O12,P12)<0,"Пауза",IF(P12>O12,"FBS","FBO")) -> FBO | R12: Авто | S12: =IF(R12="Авто",Q12,R12) -> FBO | T12: =IF(S12="FBO",O12,IF(S12="FBS",P12,0)) -> 154036.62 | U12: =IF(S12="FBS",AK12,0) -> 0 | V12: =IF(S12="FBS",AY12,0) -> 0 | X12: =ROUNDUP(G12/(1-K12),0) -> 181 | Y12: =X12-G12 -> 31 | Z12: =G12*H12 -> 523500 | AA12: =G12*I12 -> 210000 | AB12: =Z12*M12 -> 88995 | AC12: =Z12*Тарифы!$B$32 -> 7852.5 | AD12: =X12*(Тарифы!$B$18+MAX(0,J12-5)*Тарифы!$B$19) -> 14932.5 | AE12: =X12*Тарифы!$B$20 -> 4525 | AF12: =BO12*J12*$C$48*IF(E12="Крупногабарит",$C$68,Тарифы!$B$21) -> 34090.875 | AG12: =X12*J12*'Затраты продавца'!$B$12 -> 2375.625 | AH12: =Y12*(Тарифы!$B$18+MAX(0,J12-5)*Тарифы!$B$19)*Тарифы!$B$22 -> 2557.5 | AI12: =ROUNDUP(G12/(1-MIN(0.99,MAX(0,K12+$C$51)))*$C$49,0) -> 181 | AJ12: =ROUNDUP(AI12*$C$50,0) -> 19 | AK12: =AI12-AJ12 -> 162 | AL12: =ROUNDUP(AK12*MIN(0.99,MAX(0,K12+$C$51)),0) -> 28 | AM12: =AK12-AL12 -> 134 | AN12: =AM12*H12 -> 467660 | AO12: =AM12*I12 -> 187600 | AP12: =AN12*N12 -> 74825.6 | AQ12: =AN12*Тарифы!$B$32 -> 7014.9 | AR12: =AK12*(Тарифы!$B$25+MAX(0,J12-5)*Тарифы!$B$26) -> 13365 | AS12: =AK12*Тарифы!$B$27 -> 4050 | AT12: =BP12*J12*$C$48*'Затраты продавца'!$B$5 -> 11363.625 | AU12: =AK12*('Затраты продавца'!$B$6+'Затраты продавца'!$B$7) -> 11340 | AV12: =AK12*Тарифы!$B$24 -> 1620 | AW12: =AL12*((Тарифы!$B$25+MAX(0,J12-5)*Тарифы!$B$26)*Тарифы!$B$28+'Затраты продавца'!$B$9+(1-'Затраты продавца'!$B$10)*I12*$C$55) -> 10990 | AX12: =AJ12*Тарифы!$B$29 -> 2850 | AY12: =AK12*J12/1000 -> 0.8505 | AZ12: =IF(S12="FBO",G12,IF(S12="FBS",AM12,0)) -> 150 | BA12: =IF(S12="FBO",X12,IF(S12="FBS",AK12,0)) -> 181 | BB12: =IF(S12="FBO",Z12,IF(S12="FBS",AN12,0)) -> 523500 | BC12: =IF(S12="FBO",AA12,IF(S12="FBS",AO12,0)) -> 210000 | BD12: =IF(S12="FBO",AB12,IF(S12="FBS",AP12,0)) -> 88995 | BE12: =IF(S12="FBO",AC12,IF(S12="FBS",AQ12,0)) -> 7852.5 | BF12: =IF(S12="FBO",AD12,IF(S12="FBS",AR12,0)) -> 14932.5 | BG12: =IF(S12="FBO",AE12,IF(S12="FBS",AS12,0)) -> 4525 | BH12: =IF(S12="FBO",AF12,IF(S12="FBS",AT12,0)) -> 34090.875 | BI12: =IF(S12="FBO",AG12,0) -> 2375.625 | BJ12: =IF(S12="FBS",AU12,0) -> 0 | BK12: =IF(S12="FBS",AV12,0) -> 0 | BL12: =IF(S12="FBO",AH12,IF(S12="FBS",AW12,0)) -> 2557.5 | BM12: =IF(S12="FBS",AX12,0) -> 0 | BN12: =Y12*I12*(1-'Затраты продавца'!$B$10)*$C$55 -> 6510 | BO12: =ROUNDUP(X12*L12/$C$48,0) -> 481 | BP12: =ROUNDUP(AI12*L12*$C$54/$C$48,0) -> 481 | BQ12: =IF(S12="FBO",BO12,IF(S12="FBS",BP12,0)) -> 481
B13: =HYPERLINK("#'SKU'!A10","SKU!10") -> SKU!10 | C13: =SKU!A10 -> SM-0009 | D13: =SKU!B10 -> Куртка зимняя утеплённая | E13: =SKU!C10 -> Одежда | F13: =SKU!L10 -> FBO | G13: =SKU!K10*IF(SKU!L10="не представлен",$C$52,1) -> 18 | H13: =SKU!D10 -> 8990 | I13: =SKU!E10 -> 4100 | J13: =SKU!I10 -> 23.625 | K13: =SKU!N10 -> 0.2 | L13: =IF(ISNUMBER(SKU!M10),SKU!M10,$C$53) -> 140 | M13: =VLOOKUP(E13,$B$58:$D$63,2,FALSE()) -> 0.17 | N13: =VLOOKUP(E13,$B$58:$D$63,3,FALSE()) -> 0.16 | O13: =Z13-SUM(AA13:AF13)-AH13-BN13 -> 12533.05 | P13: =AN13-SUM(AO13:AX13) -> 29786.25 | Q13: =IF(MAX(O13,P13)<0,"Пауза",IF(P13>O13,"FBS","FBO")) -> FBS | R13: Авто | S13: =IF(R13="Авто",Q13,R13) -> FBS | T13: =IF(S13="FBO",O13,IF(S13="FBS",P13,0)) -> 29786.25 | U13: =IF(S13="FBS",AK13,0) -> 20 | V13: =IF(S13="FBS",AY13,0) -> 0.4725 | X13: =ROUNDUP(G13/(1-K13),0) -> 23 | Y13: =X13-G13 -> 5 | Z13: =G13*H13 -> 161820 | AA13: =G13*I13 -> 73800 | AB13: =Z13*M13 -> 27509.4 | AC13: =Z13*Тарифы!$B$32 -> 2427.3 | AD13: =X13*(Тарифы!$B$18+MAX(0,J13-5)*Тарифы!$B$19) -> 6123.75 | AE13: =X13*Тарифы!$B$20 -> 575 | AF13: =BO13*J13*$C$48*IF(E13="Крупногабарит",$C$68,Тарифы!$B$21) -> 34445.25 | AG13: =X13*J13*'Затраты продавца'!$B$12 -> 1358.4375 | AH13: =Y13*(Тарифы!$B$18+MAX(0,J13-5)*Тарифы!$B$19)*Тарифы!$B$22 -> 1331.25 | AI13: =ROUNDUP(G13/(1-MIN(0.99,MAX(0,K13+$C$51)))*$C$49,0) -> 23 | AJ13: =ROUNDUP(AI13*$C$50,0) -> 3 | AK13: =AI13-AJ13 -> 20 | AL13: =ROUNDUP(AK13*MIN(0.99,MAX(0,K13+$C$51)),0) -> 4 | AM13: =AK13-AL13 -> 16 | AN13: =AM13*H13 -> 143840 | AO13: =AM13*I13 -> 65600 | AP13: =AN13*N13 -> 23014.4 | AQ13: =AN13*Тарифы!$B$32 -> 2157.6 | AR13: =AK13*(Тарифы!$B$25+MAX(0,J13-5)*Тарифы!$B$26) -> 5325 | AS13: =AK13*Тарифы!$B$27 -> 500 | AT13: =BP13*J13*$C$48*'Затраты продавца'!$B$5 -> 11481.75 | AU13: =AK13*('Затраты продавца'!$B$6+'Затраты продавца'!$B$7) -> 1400 | AV13: =AK13*Тарифы!$B$24 -> 200 | AW13: =AL13*((Тарифы!$B$25+MAX(0,J13-5)*Тарифы!$B$26)*Тарифы!$B$28+'Затраты продавца'!$B$9+(1-'Затраты продавца'!$B$10)*I13*$C$55) -> 3925 | AX13: =AJ13*Тарифы!$B$29 -> 450 | AY13: =AK13*J13/1000 -> 0.4725 | AZ13: =IF(S13="FBO",G13,IF(S13="FBS",AM13,0)) -> 16 | BA13: =IF(S13="FBO",X13,IF(S13="FBS",AK13,0)) -> 20 | BB13: =IF(S13="FBO",Z13,IF(S13="FBS",AN13,0)) -> 143840 | BC13: =IF(S13="FBO",AA13,IF(S13="FBS",AO13,0)) -> 65600 | BD13: =IF(S13="FBO",AB13,IF(S13="FBS",AP13,0)) -> 23014.4 | BE13: =IF(S13="FBO",AC13,IF(S13="FBS",AQ13,0)) -> 2157.6 | BF13: =IF(S13="FBO",AD13,IF(S13="FBS",AR13,0)) -> 5325 | BG13: =IF(S13="FBO",AE13,IF(S13="FBS",AS13,0)) -> 500 | BH13: =IF(S13="FBO",AF13,IF(S13="FBS",AT13,0)) -> 11481.75 | BI13: =IF(S13="FBO",AG13,0) -> 0 | BJ13: =IF(S13="FBS",AU13,0) -> 1400 | BK13: =IF(S13="FBS",AV13,0) -> 200 | BL13: =IF(S13="FBO",AH13,IF(S13="FBS",AW13,0)) -> 3925 | BM13: =IF(S13="FBS",AX13,0) -> 450 | BN13: =Y13*I13*(1-'Затраты продавца'!$B$10)*$C$55 -> 3075 | BO13: =ROUNDUP(X13*L13/$C$48,0) -> 108 | BP13: =ROUNDUP(AI13*L13*$C$54/$C$48,0) -> 108 | BQ13: =IF(S13="FBO",BO13,IF(S13="FBS",BP13,0)) -> 108
B14: =HYPERLINK("#'SKU'!A11","SKU!11") -> SKU!11 | C14: =SKU!A11 -> SM-0010 | D14: =SKU!B11 -> Леггинсы женские | E14: =SKU!C11 -> Одежда | F14: =SKU!L11 -> FBO | G14: =SKU!K11*IF(SKU!L11="не представлен",$C$52,1) -> 290 | H14: =SKU!D11 -> 1790 | I14: =SKU!E11 -> 620 | J14: =SKU!I11 -> 2.24 | K14: =SKU!N11 -> 0.18 | L14: =IF(ISNUMBER(SKU!M11),SKU!M11,$C$53) -> 77.397201 | M14: =VLOOKUP(E14,$B$58:$D$63,2,FALSE()) -> 0.17 | N14: =VLOOKUP(E14,$B$58:$D$63,3,FALSE()) -> 0.16 | O14: =Z14-SUM(AA14:AF14)-AH14-BN14 -> 167385.14 | P14: =AN14-SUM(AO14:AX14) -> 133477.88 | Q14: =IF(MAX(O14,P14)<0,"Пауза",IF(P14>O14,"FBS","FBO")) -> FBO | R14: Авто | S14: =IF(R14="Авто",Q14,R14) -> FBO | T14: =IF(S14="FBO",O14,IF(S14="FBS",P14,0)) -> 167385.14 | U14: =IF(S14="FBS",AK14,0) -> 0 | V14: =IF(S14="FBS",AY14,0) -> 0 | X14: =ROUNDUP(G14/(1-K14),0) -> 354 | Y14: =X14-G14 -> 64 | Z14: =G14*H14 -> 519100 | AA14: =G14*I14 -> 179800 | AB14: =Z14*M14 -> 88247 | AC14: =Z14*Тарифы!$B$32 -> 7786.5 | AD14: =X14*(Тарифы!$B$18+MAX(0,J14-5)*Тарифы!$B$19) -> 28320 | AE14: =X14*Тарифы!$B$20 -> 8850 | AF14: =BO14*J14*$C$48*IF(E14="Крупногабарит",$C$68,Тарифы!$B$21) -> 27639.36 | AG14: =X14*J14*'Затраты продавца'!$B$12 -> 1982.4 | AH14: =Y14*(Тарифы!$B$18+MAX(0,J14-5)*Тарифы!$B$19)*Тарифы!$B$22 -> 5120 | AI14: =ROUNDUP(G14/(1-MIN(0.99,MAX(0,K14+$C$51)))*$C$49,0) -> 354 | AJ14: =ROUNDUP(AI14*$C$50,0) -> 36 | AK14: =AI14-AJ14 -> 318 | AL14: =ROUNDUP(AK14*MIN(0.99,MAX(0,K14+$C$51)),0) -> 58 | AM14: =AK14-AL14 -> 260 | AN14: =AM14*H14 -> 465400 | AO14: =AM14*I14 -> 161200 | AP14: =AN14*N14 -> 74464 | AQ14: =AN14*Тарифы!$B$32 -> 6981 | AR14: =AK14*(Тарифы!$B$25+MAX(0,J14-5)*Тарифы!$B$26) -> 25440 | AS14: =AK14*Тарифы!$B$27 -> 7950 | AT14: =BP14*J14*$C$48*'Затраты продавца'!$B$5 -> 9213.12 | AU14: =AK14*('Затраты продавца'!$B$6+'Затраты продавца'!$B$7) -> 22260 | AV14: =AK14*Тарифы!$B$24 -> 3180 | AW14: =AL14*((Тарифы!$B$25+MAX(0,J14-5)*Тарифы!$B$26)*Тарифы!$B$28+'Затраты продавца'!$B$9+(1-'Затраты продавца'!$B$10)*I14*$C$55) -> 15834 | AX14: =AJ14*Тарифы!$B$29 -> 5400 | AY14: =AK14*J14/1000 -> 0.71232 | AZ14: =IF(S14="FBO",G14,IF(S14="FBS",AM14,0)) -> 290 | BA14: =IF(S14="FBO",X14,IF(S14="FBS",AK14,0)) -> 354 | BB14: =IF(S14="FBO",Z14,IF(S14="FBS",AN14,0)) -> 519100 | BC14: =IF(S14="FBO",AA14,IF(S14="FBS",AO14,0)) -> 179800 | BD14: =IF(S14="FBO",AB14,IF(S14="FBS",AP14,0)) -> 88247 | BE14: =IF(S14="FBO",AC14,IF(S14="FBS",AQ14,0)) -> 7786.5 | BF14: =IF(S14="FBO",AD14,IF(S14="FBS",AR14,0)) -> 28320 | BG14: =IF(S14="FBO",AE14,IF(S14="FBS",AS14,0)) -> 8850 | BH14: =IF(S14="FBO",AF14,IF(S14="FBS",AT14,0)) -> 27639.36 | BI14: =IF(S14="FBO",AG14,0) -> 1982.4 | BJ14: =IF(S14="FBS",AU14,0) -> 0 | BK14: =IF(S14="FBS",AV14,0) -> 0 | BL14: =IF(S14="FBO",AH14,IF(S14="FBS",AW14,0)) -> 5120 | BM14: =IF(S14="FBS",AX14,0) -> 0 | BN14: =Y14*I14*(1-'Затраты продавца'!$B$10)*$C$55 -> 5952 | BO14: =ROUNDUP(X14*L14/$C$48,0) -> 914 | BP14: =ROUNDUP(AI14*L14*$C$54/$C$48,0) -> 914 | BQ14: =IF(S14="FBO",BO14,IF(S14="FBS",BP14,0)) -> 914
B15: =HYPERLINK("#'SKU'!A12","SKU!12") -> SKU!12 | C15: =SKU!A12 -> SM-0011 | D15: =SKU!B12 -> Гантели разборные 2×10 кг | E15: =SKU!C12 -> Фитнес | F15: =SKU!L12 -> FBO | G15: =SKU!K12*IF(SKU!L12="не представлен",$C$52,1) -> 60 | H15: =SKU!D12 -> 4990 | I15: =SKU!E12 -> 2750 | J15: =SKU!I12 -> 16.875 | K15: =SKU!N12 -> 0.03 | L15: =IF(ISNUMBER(SKU!M12),SKU!M12,$C$53) -> 81.658982 | M15: =VLOOKUP(E15,$B$58:$D$63,2,FALSE()) -> 0.15 | N15: =VLOOKUP(E15,$B$58:$D$63,3,FALSE()) -> 0.14 | O15: =Z15-SUM(AA15:AF15)-AH15-BN15 -> 31403.688 | P15: =AN15-SUM(AO15:AX15) -> 45714.963 | Q15: =IF(MAX(O15,P15)<0,"Пауза",IF(P15>O15,"FBS","FBO")) -> FBS | R15: Авто | S15: =IF(R15="Авто",Q15,R15) -> FBS | T15: =IF(S15="FBO",O15,IF(S15="FBS",P15,0)) -> 45714.963 | U15: =IF(S15="FBS",AK15,0) -> 55 | V15: =IF(S15="FBS",AY15,0) -> 0.928125 | X15: =ROUNDUP(G15/(1-K15),0) -> 62 | Y15: =X15-G15 -> 2 | Z15: =G15*H15 -> 299400 | AA15: =G15*I15 -> 165000 | AB15: =Z15*M15 -> 44910 | AC15: =Z15*Тарифы!$B$32 -> 4491 | AD15: =X15*(Тарифы!$B$18+MAX(0,J15-5)*Тарифы!$B$19) -> 12322.5 | AE15: =X15*Тарифы!$B$20 -> 1550 | AF15: =BO15*J15*$C$48*IF(E15="Крупногабарит",$C$68,Тарифы!$B$21) -> 38500.312 | AG15: =X15*J15*'Затраты продавца'!$B$12 -> 2615.625 | AH15: =Y15*(Тарифы!$B$18+MAX(0,J15-5)*Тарифы!$B$19)*Тарифы!$B$22 -> 397.5 | AI15: =ROUNDUP(G15/(1-MIN(0.99,MAX(0,K15+$C$51)))*$C$49,0) -> 62 | AJ15: =ROUNDUP(AI15*$C$50,0) -> 7 | AK15: =AI15-AJ15 -> 55 | AL15: =ROUNDUP(AK15*MIN(0.99,MAX(0,K15+$C$51)),0) -> 2 | AM15: =AK15-AL15 -> 53 | AN15: =AM15*H15 -> 264470 | AO15: =AM15*I15 -> 145750 | AP15: =AN15*N15 -> 37025.8 | AQ15: =AN15*Тарифы!$B$32 -> 3967.05 | AR15: =AK15*(Тарифы!$B$25+MAX(0,J15-5)*Тарифы!$B$26) -> 10931.25 | AS15: =AK15*Тарифы!$B$27 -> 1375 | AT15: =BP15*J15*$C$48*'Затраты продавца'!$B$5 -> 12833.438 | AU15: =AK15*('Затраты продавца'!$B$6+'Затраты продавца'!$B$7) -> 3850 | AV15: =AK15*Тарифы!$B$24 -> 550 | AW15: =AL15*((Тарифы!$B$25+MAX(0,J15-5)*Тарифы!$B$26)*Тарифы!$B$28+'Затраты продавца'!$B$9+(1-'Затраты продавца'!$B$10)*I15*$C$55) -> 1422.5 | AX15: =AJ15*Тарифы!$B$29 -> 1050 | AY15: =AK15*J15/1000 -> 0.928125 | AZ15: =IF(S15="FBO",G15,IF(S15="FBS",AM15,0)) -> 53 | BA15: =IF(S15="FBO",X15,IF(S15="FBS",AK15,0)) -> 55 | BB15: =IF(S15="FBO",Z15,IF(S15="FBS",AN15,0)) -> 264470 | BC15: =IF(S15="FBO",AA15,IF(S15="FBS",AO15,0)) -> 145750 | BD15: =IF(S15="FBO",AB15,IF(S15="FBS",AP15,0)) -> 37025.8 | BE15: =IF(S15="FBO",AC15,IF(S15="FBS",AQ15,0)) -> 3967.05 | BF15: =IF(S15="FBO",AD15,IF(S15="FBS",AR15,0)) -> 10931.25 | BG15: =IF(S15="FBO",AE15,IF(S15="FBS",AS15,0)) -> 1375 | BH15: =IF(S15="FBO",AF15,IF(S15="FBS",AT15,0)) -> 12833.438 | BI15: =IF(S15="FBO",AG15,0) -> 0 | BJ15: =IF(S15="FBS",AU15,0) -> 3850 | BK15: =IF(S15="FBS",AV15,0) -> 550 | BL15: =IF(S15="FBO",AH15,IF(S15="FBS",AW15,0)) -> 1422.5 | BM15: =IF(S15="FBS",AX15,0) -> 1050 | BN15: =Y15*I15*(1-'Затраты продавца'!$B$10)*$C$55 -> 825 | BO15: =ROUNDUP(X15*L15/$C$48,0) -> 169 | BP15: =ROUNDUP(AI15*L15*$C$54/$C$48,0) -> 169 | BQ15: =IF(S15="FBO",BO15,IF(S15="FBS",BP15,0)) -> 169
B16: =HYPERLINK("#'SKU'!A13","SKU!13") -> SKU!13 | C16: =SKU!A13 -> SM-0012 | D16: =SKU!B13 -> Гиря чугунная 16 кг | E16: =SKU!C13 -> Фитнес | F16: =SKU!L13 -> FBO | G16: =SKU!K13*IF(SKU!L13="не представлен",$C$52,1) -> 45 | H16: =SKU!D13 -> 2990 | I16: =SKU!E13 -> 1750 | J16: =SKU!I13 -> 11 | K16: =SKU!N13 -> 0.02 | L16: =IF(ISNUMBER(SKU!M13),SKU!M13,$C$53) -> 60.716212 | M16: =VLOOKUP(E16,$B$58:$D$63,2,FALSE()) -> 0.15 | N16: =VLOOKUP(E16,$B$58:$D$63,3,FALSE()) -> 0.14 | O16: =Z16-SUM(AA16:AF16)-AH16-BN16 -> 11647.75 | P16: =AN16-SUM(AO16:AX16) -> 15111.5 | Q16: =IF(MAX(O16,P16)<0,"Пауза",IF(P16>O16,"FBS","FBO")) -> FBS | R16: Авто | S16: =IF(R16="Авто",Q16,R16) -> FBS | T16: =IF(S16="FBO",O16,IF(S16="FBS",P16,0)) -> 15111.5 | U16: =IF(S16="FBS",AK16,0) -> 41 | V16: =IF(S16="FBS",AY16,0) -> 0.451 | X16: =ROUNDUP(G16/(1-K16),0) -> 46 | Y16: =X16-G16 -> 1 | Z16: =G16*H16 -> 134550 | AA16: =G16*I16 -> 78750 | AB16: =Z16*M16 -> 20182.5 | AC16: =Z16*Тарифы!$B$32 -> 2018.25 | AD16: =X16*(Тарифы!$B$18+MAX(0,J16-5)*Тарифы!$B$19) -> 6440 | AE16: =X16*Тарифы!$B$20 -> 1150 | AF16: =BO16*J16*$C$48*IF(E16="Крупногабарит",$C$68,Тарифы!$B$21) -> 13959 | AG16: =X16*J16*'Затраты продавца'!$B$12 -> 1265 | AH16: =Y16*(Тарифы!$B$18+MAX(0,J16-5)*Тарифы!$B$19)*Тарифы!$B$22 -> 140 | AI16: =ROUNDUP(G16/(1-MIN(0.99,MAX(0,K16+$C$51)))*$C$49,0) -> 46 | AJ16: =ROUNDUP(AI16*$C$50,0) -> 5 | AK16: =AI16-AJ16 -> 41 | AL16: =ROUNDUP(AK16*MIN(0.99,MAX(0,K16+$C$51)),0) -> 1 | AM16: =AK16-AL16 -> 40 | AN16: =AM16*H16 -> 119600 | AO16: =AM16*I16 -> 70000 | AP16: =AN16*N16 -> 16744 | AQ16: =AN16*Тарифы!$B$32 -> 1794 | AR16: =AK16*(Тарифы!$B$25+MAX(0,J16-5)*Тарифы!$B$26) -> 5740 | AS16: =AK16*Тарифы!$B$27 -> 1025 | AT16: =BP16*J16*$C$48*'Затраты продавца'!$B$5 -> 4653 | AU16: =AK16*('Затраты продавца'!$B$6+'Затраты продавца'!$B$7) -> 2870 | AV16: =AK16*Тарифы!$B$24 -> 410 | AW16: =AL16*((Тарифы!$B$25+MAX(0,J16-5)*Тарифы!$B$26)*Тарифы!$B$28+'Затраты продавца'!$B$9+(1-'Затраты продавца'!$B$10)*I16*$C$55) -> 502.5 | AX16: =AJ16*Тарифы!$B$29 -> 750 | AY16: =AK16*J16/1000 -> 0.451 | AZ16: =IF(S16="FBO",G16,IF(S16="FBS",AM16,0)) -> 40 | BA16: =IF(S16="FBO",X16,IF(S16="FBS",AK16,0)) -> 41 | BB16: =IF(S16="FBO",Z16,IF(S16="FBS",AN16,0)) -> 119600 | BC16: =IF(S16="FBO",AA16,IF(S16="FBS",AO16,0)) -> 70000 | BD16: =IF(S16="FBO",AB16,IF(S16="FBS",AP16,0)) -> 16744 | BE16: =IF(S16="FBO",AC16,IF(S16="FBS",AQ16,0)) -> 1794 | BF16: =IF(S16="FBO",AD16,IF(S16="FBS",AR16,0)) -> 5740 | BG16: =IF(S16="FBO",AE16,IF(S16="FBS",AS16,0)) -> 1025 | BH16: =IF(S16="FBO",AF16,IF(S16="FBS",AT16,0)) -> 4653 | BI16: =IF(S16="FBO",AG16,0) -> 0 | BJ16: =IF(S16="FBS",AU16,0) -> 2870 | BK16: =IF(S16="FBS",AV16,0) -> 410 | BL16: =IF(S16="FBO",AH16,IF(S16="FBS",AW16,0)) -> 502.5 | BM16: =IF(S16="FBS",AX16,0) -> 750 | BN16: =Y16*I16*(1-'Затраты продавца'!$B$10)*$C$55 -> 262.5 | BO16: =ROUNDUP(X16*L16/$C$48,0) -> 94 | BP16: =ROUNDUP(AI16*L16*$C$54/$C$48,0) -> 94 | BQ16: =IF(S16="FBO",BO16,IF(S16="FBS",BP16,0)) -> 94
B17: =HYPERLINK("#'SKU'!A14","SKU!14") -> SKU!14 | C17: =SKU!A14 -> SM-0013 | D17: =SKU!B14 -> Коврик для йоги 6 мм | E17: =SKU!C14 -> Фитнес | F17: =SKU!L14 -> FBO | G17: =SKU!K14*IF(SKU!L14="не представлен",$C$52,1) -> 320 | H17: =SKU!D14 -> 1490 | I17: =SKU!E14 -> 520 | J17: =SKU!I14 -> 14.85 | K17: =SKU!N14 -> 0.04 | L17: =IF(ISNUMBER(SKU!M14),SKU!M14,$C$53) -> 88.153619 | M17: =VLOOKUP(E17,$B$58:$D$63,2,FALSE()) -> 0.15 | N17: =VLOOKUP(E17,$B$58:$D$63,3,FALSE()) -> 0.14 | O17: =Z17-SUM(AA17:AF17)-AH17-BN17 -> -36698.45 | P17: =AN17-SUM(AO17:AX17) -> 52796.25 | Q17: =IF(MAX(O17,P17)<0,"Пауза",IF(P17>O17,"FBS","FBO")) -> FBS | R17: Авто | S17: =IF(R17="Авто",Q17,R17) -> FBS | T17: =IF(S17="FBO",O17,IF(S17="FBS",P17,0)) -> 52796.25 | U17: =IF(S17="FBS",AK17,0) -> 300 | V17: =IF(S17="FBS",AY17,0) -> 4.455 | X17: =ROUNDUP(G17/(1-K17),0) -> 334 | Y17: =X17-G17 -> 14 | Z17: =G17*H17 -> 476800 | AA17: =G17*I17 -> 166400 | AB17: =Z17*M17 -> 71520 | AC17: =Z17*Тарифы!$B$32 -> 7152 | AD17: =X17*(Тарифы!$B$18+MAX(0,J17-5)*Тарифы!$B$19) -> 59619 | AE17: =X17*Тарифы!$B$20 -> 8350 | AF17: =BO17*J17*$C$48*IF(E17="Крупногабарит",$C$68,Тарифы!$B$21) -> 196866.45 | AG17: =X17*J17*'Затраты продавца'!$B$12 -> 12399.75 | AH17: =Y17*(Тарифы!$B$18+MAX(0,J17-5)*Тарифы!$B$19)*Тарифы!$B$22 -> 2499 | AI17: =ROUNDUP(G17/(1-MIN(0.99,MAX(0,K17+$C$51)))*$C$49,0) -> 334 | AJ17: =ROUNDUP(AI17*$C$50,0) -> 34 | AK17: =AI17-AJ17 -> 300 | AL17: =ROUNDUP(AK17*MIN(0.99,MAX(0,K17+$C$51)),0) -> 12 | AM17: =AK17-AL17 -> 288 | AN17: =AM17*H17 -> 429120 | AO17: =AM17*I17 -> 149760 | AP17: =AN17*N17 -> 60076.8 | AQ17: =AN17*Тарифы!$B$32 -> 6436.8 | AR17: =AK17*(Тарифы!$B$25+MAX(0,J17-5)*Тарифы!$B$26) -> 53550 | AS17: =AK17*Тарифы!$B$27 -> 7500 | AT17: =BP17*J17*$C$48*'Затраты продавца'!$B$5 -> 65622.15 | AU17: =AK17*('Затраты продавца'!$B$6+'Затраты продавца'!$B$7) -> 21000 | AV17: =AK17*Тарифы!$B$24 -> 3000 | AW17: =AL17*((Тарифы!$B$25+MAX(0,J17-5)*Тарифы!$B$26)*Тарифы!$B$28+'Затраты продавца'!$B$9+(1-'Затраты продавца'!$B$10)*I17*$C$55) -> 4278 | AX17: =AJ17*Тарифы!$B$29 -> 5100 | AY17: =AK17*J17/1000 -> 4.455 | AZ17: =IF(S17="FBO",G17,IF(S17="FBS",AM17,0)) -> 288 | BA17: =IF(S17="FBO",X17,IF(S17="FBS",AK17,0)) -> 300 | BB17: =IF(S17="FBO",Z17,IF(S17="FBS",AN17,0)) -> 429120 | BC17: =IF(S17="FBO",AA17,IF(S17="FBS",AO17,0)) -> 149760 | BD17: =IF(S17="FBO",AB17,IF(S17="FBS",AP17,0)) -> 60076.8 | BE17: =IF(S17="FBO",AC17,IF(S17="FBS",AQ17,0)) -> 6436.8 | BF17: =IF(S17="FBO",AD17,IF(S17="FBS",AR17,0)) -> 53550 | BG17: =IF(S17="FBO",AE17,IF(S17="FBS",AS17,0)) -> 7500 | BH17: =IF(S17="FBO",AF17,IF(S17="FBS",AT17,0)) -> 65622.15 | BI17: =IF(S17="FBO",AG17,0) -> 0 | BJ17: =IF(S17="FBS",AU17,0) -> 21000 | BK17: =IF(S17="FBS",AV17,0) -> 3000 | BL17: =IF(S17="FBO",AH17,IF(S17="FBS",AW17,0)) -> 4278 | BM17: =IF(S17="FBS",AX17,0) -> 5100 | BN17: =Y17*I17*(1-'Затраты продавца'!$B$10)*$C$55 -> 1092 | BO17: =ROUNDUP(X17*L17/$C$48,0) -> 982 | BP17: =ROUNDUP(AI17*L17*$C$54/$C$48,0) -> 982 | BQ17: =IF(S17="FBO",BO17,IF(S17="FBS",BP17,0)) -> 982
B18: =HYPERLINK("#'SKU'!A15","SKU!15") -> SKU!15 | C18: =SKU!A15 -> SM-0014 | D18: =SKU!B15 -> Набор эспандеров | E18: =SKU!C15 -> Фитнес | F18: =SKU!L15 -> FBO | G18: =SKU!K15*IF(SKU!L15="не представлен",$C$52,1) -> 410 | H18: =SKU!D15 -> 790 | I18: =SKU!E15 -> 260 | J18: =SKU!I15 -> 1.296 | K18: =SKU!N15 -> 0.04 | L18: =IF(ISNUMBER(SKU!M15),SKU!M15,$C$53) -> 44.843155 | M18: =VLOOKUP(E18,$B$58:$D$63,2,FALSE()) -> 0.15 | N18: =VLOOKUP(E18,$B$58:$D$63,3,FALSE()) -> 0.14 | O18: =Z18-SUM(AA18:AF18)-AH18-BN18 -> 105577.06 | P18: =AN18-SUM(AO18:AX18) -> 65474.47 | Q18: =IF(MAX(O18,P18)<0,"Пауза",IF(P18>O18,"FBS","FBO")) -> FBO | R18: Авто | S18: =IF(R18="Авто",Q18,R18) -> FBO | T18: =IF(S18="FBO",O18,IF(S18="FBS",P18,0)) -> 105577.06 | U18: =IF(S18="FBS",AK18,0) -> 0 | V18: =IF(S18="FBS",AY18,0) -> 0 | X18: =ROUNDUP(G18/(1-K18),0) -> 428 | Y18: =X18-G18 -> 18 | Z18: =G18*H18 -> 323900 | AA18: =G18*I18 -> 106600 | AB18: =Z18*M18 -> 48585 | AC18: =Z18*Тарифы!$B$32 -> 4858.5 | AD18: =X18*(Тарифы!$B$18+MAX(0,J18-5)*Тарифы!$B$19) -> 34240 | AE18: =X18*Тарифы!$B$20 -> 10700 | AF18: =BO18*J18*$C$48*IF(E18="Крупногабарит",$C$68,Тарифы!$B$21) -> 11197.44 | AG18: =X18*J18*'Затраты продавца'!$B$12 -> 1386.72 | AH18: =Y18*(Тарифы!$B$18+MAX(0,J18-5)*Тарифы!$B$19)*Тарифы!$B$22 -> 1440 | AI18: =ROUNDUP(G18/(1-MIN(0.99,MAX(0,K18+$C$51)))*$C$49,0) -> 428 | AJ18: =ROUNDUP(AI18*$C$50,0) -> 43 | AK18: =AI18-AJ18 -> 385 | AL18: =ROUNDUP(AK18*MIN(0.99,MAX(0,K18+$C$51)),0) -> 16 | AM18: =AK18-AL18 -> 369 | AN18: =AM18*H18 -> 291510 | AO18: =AM18*I18 -> 95940 | AP18: =AN18*N18 -> 40811.4 | AQ18: =AN18*Тарифы!$B$32 -> 4372.65 | AR18: =AK18*(Тарифы!$B$25+MAX(0,J18-5)*Тарифы!$B$26) -> 30800 | AS18: =AK18*Тарифы!$B$27 -> 9625 | AT18: =BP18*J18*$C$48*'Затраты продавца'!$B$5 -> 3732.48 | AU18: =AK18*('Затраты продавца'!$B$6+'Затраты продавца'!$B$7) -> 26950 | AV18: =AK18*Тарифы!$B$24 -> 3850 | AW18: =AL18*((Тарифы!$B$25+MAX(0,J18-5)*Тарифы!$B$26)*Тарифы!$B$28+'Затраты продавца'!$B$9+(1-'Затраты продавца'!$B$10)*I18*$C$55) -> 3504 | AX18: =AJ18*Тарифы!$B$29 -> 6450 | AY18: =AK18*J18/1000 -> 0.49896 | AZ18: =IF(S18="FBO",G18,IF(S18="FBS",AM18,0)) -> 410 | BA18: =IF(S18="FBO",X18,IF(S18="FBS",AK18,0)) -> 428 | BB18: =IF(S18="FBO",Z18,IF(S18="FBS",AN18,0)) -> 323900 | BC18: =IF(S18="FBO",AA18,IF(S18="FBS",AO18,0)) -> 106600 | BD18: =IF(S18="FBO",AB18,IF(S18="FBS",AP18,0)) -> 48585 | BE18: =IF(S18="FBO",AC18,IF(S18="FBS",AQ18,0)) -> 4858.5 | BF18: =IF(S18="FBO",AD18,IF(S18="FBS",AR18,0)) -> 34240 | BG18: =IF(S18="FBO",AE18,IF(S18="FBS",AS18,0)) -> 10700 | BH18: =IF(S18="FBO",AF18,IF(S18="FBS",AT18,0)) -> 11197.44 | BI18: =IF(S18="FBO",AG18,0) -> 1386.72 | BJ18: =IF(S18="FBS",AU18,0) -> 0 | BK18: =IF(S18="FBS",AV18,0) -> 0 | BL18: =IF(S18="FBO",AH18,IF(S18="FBS",AW18,0)) -> 1440 | BM18: =IF(S18="FBS",AX18,0) -> 0 | BN18: =Y18*I18*(1-'Затраты продавца'!$B$10)*$C$55 -> 702 | BO18: =ROUNDUP(X18*L18/$C$48,0) -> 640 | BP18: =ROUNDUP(AI18*L18*$C$54/$C$48,0) -> 640 | BQ18: =IF(S18="FBO",BO18,IF(S18="FBS",BP18,0)) -> 640
B19: =HYPERLINK("#'SKU'!A16","SKU!16") -> SKU!16 | C19: =SKU!A16 -> SM-0015 | D19: =SKU!B16 -> Скакалка скоростная | E19: =SKU!C16 -> Аксессуары | F19: =SKU!L16 -> FBO | G19: =SKU!K16*IF(SKU!L16="не представлен",$C$52,1) -> 370 | H19: =SKU!D16 -> 490 | I19: =SKU!E16 -> 150 | J19: =SKU!I16 -> 0.96 | K19: =SKU!N16 -> 0.03 | L19: =IF(ISNUMBER(SKU!M16),SKU!M16,$C$53) -> 79.62719 | M19: =VLOOKUP(E19,$B$58:$D$63,2,FALSE()) -> 0.18 | N19: =VLOOKUP(E19,$B$58:$D$63,3,FALSE()) -> 0.17 | O19: =Z19-SUM(AA19:AF19)-AH19-BN19 -> 35965.06 | P19: =AN19-SUM(AO19:AX19) -> 6871.22 | Q19: =IF(MAX(O19,P19)<0,"Пауза",IF(P19>O19,"FBS","FBO")) -> FBO | R19: Авто | S19: =IF(R19="Авто",Q19,R19) -> FBO | T19: =IF(S19="FBO",O19,IF(S19="FBS",P19,0)) -> 35965.06 | U19: =IF(S19="FBS",AK19,0) -> 0 | V19: =IF(S19="FBS",AY19,0) -> 0 | X19: =ROUNDUP(G19/(1-K19),0) -> 382 | Y19: =X19-G19 -> 12 | Z19: =G19*H19 -> 181300 | AA19: =G19*I19 -> 55500 | AB19: =Z19*M19 -> 32634 | AC19: =Z19*Тарифы!$B$32 -> 2719.5 | AD19: =X19*(Тарифы!$B$18+MAX(0,J19-5)*Тарифы!$B$19) -> 30560 | AE19: =X19*Тарифы!$B$20 -> 9550 | AF19: =BO19*J19*$C$48*IF(E19="Крупногабарит",$C$68,Тарифы!$B$21) -> 13141.44 | AG19: =X19*J19*'Затраты продавца'!$B$12 -> 916.8 | AH19: =Y19*(Тарифы!$B$18+MAX(0,J19-5)*Тарифы!$B$19)*Тарифы!$B$22 -> 960 | AI19: =ROUNDUP(G19/(1-MIN(0.99,MAX(0,K19+$C$51)))*$C$49,0) -> 382 | AJ19: =ROUNDUP(AI19*$C$50,0) -> 39 | AK19: =AI19-AJ19 -> 343 | AL19: =ROUNDUP(AK19*MIN(0.99,MAX(0,K19+$C$51)),0) -> 11 | AM19: =AK19-AL19 -> 332 | AN19: =AM19*H19 -> 162680 | AO19: =AM19*I19 -> 49800 | AP19: =AN19*N19 -> 27655.6 | AQ19: =AN19*Тарифы!$B$32 -> 2440.2 | AR19: =AK19*(Тарифы!$B$25+MAX(0,J19-5)*Тарифы!$B$26) -> 27440 | AS19: =AK19*Тарифы!$B$27 -> 8575 | AT19: =BP19*J19*$C$48*'Затраты продавца'!$B$5 -> 4380.48 | AU19: =AK19*('Затраты продавца'!$B$6+'Затраты продавца'!$B$7) -> 24010 | AV19: =AK19*Тарифы!$B$24 -> 3430 | AW19: =AL19*((Тарифы!$B$25+MAX(0,J19-5)*Тарифы!$B$26)*Тарифы!$B$28+'Затраты продавца'!$B$9+(1-'Затраты продавца'!$B$10)*I19*$C$55) -> 2227.5 | AX19: =AJ19*Тарифы!$B$29 -> 5850 | AY19: =AK19*J19/1000 -> 0.32928 | AZ19: =IF(S19="FBO",G19,IF(S19="FBS",AM19,0)) -> 370 | BA19: =IF(S19="FBO",X19,IF(S19="FBS",AK19,0)) -> 382 | BB19: =IF(S19="FBO",Z19,IF(S19="FBS",AN19,0)) -> 181300 | BC19: =IF(S19="FBO",AA19,IF(S19="FBS",AO19,0)) -> 55500 | BD19: =IF(S19="FBO",AB19,IF(S19="FBS",AP19,0)) -> 32634 | BE19: =IF(S19="FBO",AC19,IF(S19="FBS",AQ19,0)) -> 2719.5 | BF19: =IF(S19="FBO",AD19,IF(S19="FBS",AR19,0)) -> 30560 | BG19: =IF(S19="FBO",AE19,IF(S19="FBS",AS19,0)) -> 9550 | BH19: =IF(S19="FBO",AF19,IF(S19="FBS",AT19,0)) -> 13141.44 | BI19: =IF(S19="FBO",AG19,0) -> 916.8 | BJ19: =IF(S19="FBS",AU19,0) -> 0 | BK19: =IF(S19="FBS",AV19,0) -> 0 | BL19: =IF(S19="FBO",AH19,IF(S19="FBS",AW19,0)) -> 960 | BM19: =IF(S19="FBS",AX19,0) -> 0 | BN19: =Y19*I19*(1-'Затраты продавца'!$B$10)*$C$55 -> 270 | BO19: =ROUNDUP(X19*L19/$C$48,0) -> 1014 | BP19: =ROUNDUP(AI19*L19*$C$54/$C$48,0) -> 1014 | BQ19: =IF(S19="FBO",BO19,IF(S19="FBS",BP19,0)) -> 1014
B20: =HYPERLINK("#'SKU'!A17","SKU!17") -> SKU!17 | C20: =SKU!A17 -> SM-0016 | D20: =SKU!B17 -> Палатка 2-местная | E20: =SKU!C17 -> Туризм | F20: =SKU!L17 -> FBO | G20: =SKU!K17*IF(SKU!L17="не представлен",$C$52,1) -> 45 | H20: =SKU!D17 -> 6990 | I20: =SKU!E17 -> 3200 | J20: =SKU!I17 -> 23.2 | K20: =SKU!N17 -> 0.06 | L20: =IF(ISNUMBER(SKU!M17),SKU!M17,$C$53) -> 44.53253 | M20: =VLOOKUP(E20,$B$58:$D$63,2,FALSE()) -> 0.15 | N20: =VLOOKUP(E20,$B$58:$D$63,3,FALSE()) -> 0.14 | O20: =Z20-SUM(AA20:AF20)-AH20-BN20 -> 80096.85 | P20: =AN20-SUM(AO20:AX20) -> 81688.2 | Q20: =IF(MAX(O20,P20)<0,"Пауза",IF(P20>O20,"FBS","FBO")) -> FBS | R20: Авто | S20: =IF(R20="Авто",Q20,R20) -> FBS | T20: =IF(S20="FBO",O20,IF(S20="FBS",P20,0)) -> 81688.2 | U20: =IF(S20="FBS",AK20,0) -> 43 | V20: =IF(S20="FBS",AY20,0) -> 0.9976 | X20: =ROUNDUP(G20/(1-K20),0) -> 48 | Y20: =X20-G20 -> 3 | Z20: =G20*H20 -> 314550 | AA20: =G20*I20 -> 144000 | AB20: =Z20*M20 -> 47182.5 | AC20: =Z20*Тарифы!$B$32 -> 4718.25 | AD20: =X20*(Тарифы!$B$18+MAX(0,J20-5)*Тарифы!$B$19) -> 12576 | AE20: =X20*Тарифы!$B$20 -> 1200 | AF20: =BO20*J20*$C$48*IF(E20="Крупногабарит",$C$68,Тарифы!$B$21) -> 22550.4 | AG20: =X20*J20*'Затраты продавца'!$B$12 -> 2784 | AH20: =Y20*(Тарифы!$B$18+MAX(0,J20-5)*Тарифы!$B$19)*Тарифы!$B$22 -> 786 | AI20: =ROUNDUP(G20/(1-MIN(0.99,MAX(0,K20+$C$51)))*$C$49,0) -> 48 | AJ20: =ROUNDUP(AI20*$C$50,0) -> 5 | AK20: =AI20-AJ20 -> 43 | AL20: =ROUNDUP(AK20*MIN(0.99,MAX(0,K20+$C$51)),0) -> 3 | AM20: =AK20-AL20 -> 40 | AN20: =AM20*H20 -> 279600 | AO20: =AM20*I20 -> 128000 | AP20: =AN20*N20 -> 39144 | AQ20: =AN20*Тарифы!$B$32 -> 4194 | AR20: =AK20*(Тарифы!$B$25+MAX(0,J20-5)*Тарифы!$B$26) -> 11266 | AS20: =AK20*Тарифы!$B$27 -> 1075 | AT20: =BP20*J20*$C$48*'Затраты продавца'!$B$5 -> 7516.8 | AU20: =AK20*('Затраты продавца'!$B$6+'Затраты продавца'!$B$7) -> 3010 | AV20: =AK20*Тарифы!$B$24 -> 430 | AW20: =AL20*((Тарифы!$B$25+MAX(0,J20-5)*Тарифы!$B$26)*Тарифы!$B$28+'Затраты продавца'!$B$9+(1-'Затраты продавца'!$B$10)*I20*$C$55) -> 2526 | AX20: =AJ20*Тарифы!$B$29 -> 750 | AY20: =AK20*J20/1000 -> 0.9976 | AZ20: =IF(S20="FBO",G20,IF(S20="FBS",AM20,0)) -> 40 | BA20: =IF(S20="FBO",X20,IF(S20="FBS",AK20,0)) -> 43 | BB20: =IF(S20="FBO",Z20,IF(S20="FBS",AN20,0)) -> 279600 | BC20: =IF(S20="FBO",AA20,IF(S20="FBS",AO20,0)) -> 128000 | BD20: =IF(S20="FBO",AB20,IF(S20="FBS",AP20,0)) -> 39144 | BE20: =IF(S20="FBO",AC20,IF(S20="FBS",AQ20,0)) -> 4194 | BF20: =IF(S20="FBO",AD20,IF(S20="FBS",AR20,0)) -> 11266 | BG20: =IF(S20="FBO",AE20,IF(S20="FBS",AS20,0)) -> 1075 | BH20: =IF(S20="FBO",AF20,IF(S20="FBS",AT20,0)) -> 7516.8 | BI20: =IF(S20="FBO",AG20,0) -> 0 | BJ20: =IF(S20="FBS",AU20,0) -> 3010 | BK20: =IF(S20="FBS",AV20,0) -> 430 | BL20: =IF(S20="FBO",AH20,IF(S20="FBS",AW20,0)) -> 2526 | BM20: =IF(S20="FBS",AX20,0) -> 750 | BN20: =Y20*I20*(1-'Затраты продавца'!$B$10)*$C$55 -> 1440 | BO20: =ROUNDUP(X20*L20/$C$48,0) -> 72 | BP20: =ROUNDUP(AI20*L20*$C$54/$C$48,0) -> 72 | BQ20: =IF(S20="FBO",BO20,IF(S20="FBS",BP20,0)) -> 72
B21: =HYPERLINK("#'SKU'!A18","SKU!18") -> SKU!18 | C21: =SKU!A18 -> SM-0017 | D21: =SKU!B18 -> Палатка 4-местная | E21: =SKU!C18 -> Туризм | F21: =SKU!L18 -> FBO | G21: =SKU!K18*IF(SKU!L18="не представлен",$C$52,1) -> 22 | H21: =SKU!D18 -> 12990 | I21: =SKU!E18 -> 6100 | J21: =SKU!I18 -> 45.968 | K21: =SKU!N18 -> 0.07 | L21: =IF(ISNUMBER(SKU!M18),SKU!M18,$C$53) -> 47.409611 | M21: =VLOOKUP(E21,$B$58:$D$63,2,FALSE()) -> 0.15 | N21: =VLOOKUP(E21,$B$58:$D$63,3,FALSE()) -> 0.14 | O21: =Z21-SUM(AA21:AF21)-AH21-BN21 -> 65683.036 | P21: =AN21-SUM(AO21:AX21) -> 68846.282 | Q21: =IF(MAX(O21,P21)<0,"Пауза",IF(P21>O21,"FBS","FBO")) -> FBS | R21: Авто | S21: =IF(R21="Авто",Q21,R21) -> FBS | T21: =IF(S21="FBO",O21,IF(S21="FBS",P21,0)) -> 68846.282 | U21: =IF(S21="FBS",AK21,0) -> 21 | V21: =IF(S21="FBS",AY21,0) -> 0.965328 | X21: =ROUNDUP(G21/(1-K21),0) -> 24 | Y21: =X21-G21 -> 2 | Z21: =G21*H21 -> 285780 | AA21: =G21*I21 -> 134200 | AB21: =Z21*M21 -> 42867 | AC21: =Z21*Тарифы!$B$32 -> 4286.7 | AD21: =X21*(Тарифы!$B$18+MAX(0,J21-5)*Тарифы!$B$19) -> 11752.32 | AE21: =X21*Тарифы!$B$20 -> 600 | AF21: =BO21*J21*$C$48*IF(E21="Крупногабарит",$C$68,Тарифы!$B$21) -> 23581.584 | AG21: =X21*J21*'Затраты продавца'!$B$12 -> 2758.08 | AH21: =Y21*(Тарифы!$B$18+MAX(0,J21-5)*Тарифы!$B$19)*Тарифы!$B$22 -> 979.36 | AI21: =ROUNDUP(G21/(1-MIN(0.99,MAX(0,K21+$C$51)))*$C$49,0) -> 24 | AJ21: =ROUNDUP(AI21*$C$50,0) -> 3 | AK21: =AI21-AJ21 -> 21 | AL21: =ROUNDUP(AK21*MIN(0.99,MAX(0,K21+$C$51)),0) -> 2 | AM21: =AK21-AL21 -> 19 | AN21: =AM21*H21 -> 246810 | AO21: =AM21*I21 -> 115900 | AP21: =AN21*N21 -> 34553.4 | AQ21: =AN21*Тарифы!$B$32 -> 3702.15 | AR21: =AK21*(Тарифы!$B$25+MAX(0,J21-5)*Тарифы!$B$26) -> 10283.28 | AS21: =AK21*Тарифы!$B$27 -> 525 | AT21: =BP21*J21*$C$48*'Затраты продавца'!$B$5 -> 7860.528 | AU21: =AK21*('Затраты продавца'!$B$6+'Затраты продавца'!$B$7) -> 1470 | AV21: =AK21*Тарифы!$B$24 -> 210 | AW21: =AL21*((Тарифы!$B$25+MAX(0,J21-5)*Тарифы!$B$26)*Тарифы!$B$28+'Затраты продавца'!$B$9+(1-'Затраты продавца'!$B$10)*I21*$C$55) -> 3009.36 | AX21: =AJ21*Тарифы!$B$29 -> 450 | AY21: =AK21*J21/1000 -> 0.965328 | AZ21: =IF(S21="FBO",G21,IF(S21="FBS",AM21,0)) -> 19 | BA21: =IF(S21="FBO",X21,IF(S21="FBS",AK21,0)) -> 21 | BB21: =IF(S21="FBO",Z21,IF(S21="FBS",AN21,0)) -> 246810 | BC21: =IF(S21="FBO",AA21,IF(S21="FBS",AO21,0)) -> 115900 | BD21: =IF(S21="FBO",AB21,IF(S21="FBS",AP21,0)) -> 34553.4 | BE21: =IF(S21="FBO",AC21,IF(S21="FBS",AQ21,0)) -> 3702.15 | BF21: =IF(S21="FBO",AD21,IF(S21="FBS",AR21,0)) -> 10283.28 | BG21: =IF(S21="FBO",AE21,IF(S21="FBS",AS21,0)) -> 525 | BH21: =IF(S21="FBO",AF21,IF(S21="FBS",AT21,0)) -> 7860.528 | BI21: =IF(S21="FBO",AG21,0) -> 0 | BJ21: =IF(S21="FBS",AU21,0) -> 1470 | BK21: =IF(S21="FBS",AV21,0) -> 210 | BL21: =IF(S21="FBO",AH21,IF(S21="FBS",AW21,0)) -> 3009.36 | BM21: =IF(S21="FBS",AX21,0) -> 450 | BN21: =Y21*I21*(1-'Затраты продавца'!$B$10)*$C$55 -> 1830 | BO21: =ROUNDUP(X21*L21/$C$48,0) -> 38 | BP21: =ROUNDUP(AI21*L21*$C$54/$C$48,0) -> 38 | BQ21: =IF(S21="FBO",BO21,IF(S21="FBS",BP21,0)) -> 38
